Workbook

Sheet 2026 Puntos
D1: Amarilla - Llego Tarde
D2: Roja - Llego Tarde o No pago
D3: Cupo ExPat
F4: 46002 | H4: =F$4+7 -> 46009 | N4: =H$4+7 -> 46016 | R4: =N$4+7 -> 46023 | V4: =R$4+7 -> 46030 | AB4: =V$4+7 -> 46037 | AH4: =AB$4+7 -> 46044 | AN4: =AH$4+7 -> 46051 | AT4: =AN$4+7 -> 46058 | AZ4: =AT$4+7 -> 46065 | BF4: =AZ$4+7 -> 46072 | BL4: =BF$4+7 -> 46079 | BR4: =BL$4+7 -> 46086 | BX4: =BR$4+7 -> 46093 | CD4: =BX$4+7 -> 46100 | CJ4: =CD$4+7 -> 46107 | CP4: =CJ$4+7 -> 46114 | CV4: =CP$4+7 -> 46121 | DB4: =CV$4+7 -> 46128 | DH4: =DB$4+7 -> 46135 | DN4: =DH$4+7 -> 46142 | DT4: =DN$4+7 -> 46149 | DZ4: =DT$4+7 -> 46156 | EF4: =DZ$4+7 -> 46163 | EL4: =EF$4+7 -> 46170 | ER4: =EL$4+7 -> 46177 | EX4: =ER$4+7 -> 46184 | FD4: =EX$4+7 -> 46191 | FJ4: =FD$4+7 -> 46198 | FP4: =FJ$4+7 -> 46205 | FV4: =FP$4+7 -> 46212 | GB4: =FV$4+7 -> 46219 | GH4: =GB$4+7 -> 46226 | GN4: =GH$4+7 -> 46233 | GT4: =GN$4+7 -> 46240 | GZ4: =GT$4+7 -> 46247 | HF4: =GZ$4+7 -> 46254 | HL4: =HF$4+7 -> 46261 | HR4: =HL$4+7 -> 46268 | HX4: =HR$4+7 -> 46275 | ID4: =HX$4+7 -> 46282 | IJ4: =ID$4+7 -> 46289
A5: Galactico | B5: Bullying | C5: Posicion | D5: TDP | E5: Puntos | F5: Sede | G5: Pts | H5: RSVP | I5: Jugo | J5: Sede | K5: Pts | L5: Pago | M5: PtosFecha | N5: RSVP | O5: Jugo | P5: Sede | Q5: Pts | R5: RSVP | S5: Jugo | T5: Sede | U5: Pts | V5: RSVP | W5: Jugo | X5: Sede | Y5: Pts | Z5: Pago | AA5: PtosFecha | AB5: RSVP | AC5: Jugo | AD5: Sede | AE5: Pts | AF5: Pago | AG5: PtosFecha | AH5: RSVP | AI5: Jugo | AJ5: Sede | AK5: Pts | AL5: Pago/Tarde | AM5: PtosFecha | AN5: RSVP | AO5: Jugo | AP5: Sede | AQ5: Pts | AR5: Pago/Tarde | AS5: PtosFecha | AT5: RSVP | AU5: Jugo | AV5: Sede | AW5: Pts | AX5: Pago/Tarde | AY5: PtosFecha | AZ5: RSVP | BA5: Jugo | BB5: Sede | BC5: Pts | BD5: Pago/Tarde | BE5: PtosFecha | BF5: RSVP | BG5: Jugo | BH5: Sede | BI5: Pts | BJ5: Pago/Tarde | BK5: PtosFecha | BL5: RSVP | BM5: Jugo | BN5: Sede | BO5: Pts | BP5: Pago/Tarde | BQ5: PtosFecha | BR5: RSVP | BS5: Jugo | BT5: Sede | BU5: Pts | BV5: Pago/Tarde | BW5: PtosFecha | BX5: RSVP | BY5: Jugo | BZ5: Sede | CA5: Pts | CB5: Pago/Tarde | CC5: PtosFecha | CD5: RSVP | CE5: Jugo | CF5: Sede | CG5: Pts | CH5: Pago/Tarde | CI5: PtosFecha | CJ5: RSVP | CK5: Jugo | CL5: Sede | CM5: Pts | CN5: Pago/Tarde | CO5: PtosFecha | CP5: RSVP | CQ5: Jugo | CR5: Sede | CS5: Pts | CT5: Pago/Tarde | CU5: PtosFecha | CV5: RSVP | CW5: Jugo | CX5: Sede | CY5: Pts | CZ5: Pago/Tarde | DA5: PtosFecha | DB5: RSVP | DC5: Jugo | DD5: Sede | DE5: Pts | DF5: Pago/Tarde | DG5: PtosFecha | DH5: RSVP | DI5: Jugo | DJ5: Sede | DK5: Pts | DL5: Pago/Tarde | DM5: PtosFecha | DN5: RSVP | DO5: Jugo | DP5: Sede | DQ5: Pts | DR5: Pago/Tarde | DS5: PtosFecha | DT5: RSVP | DU5: Jugo | DV5: Sede | DW5: Pts | DX5: Pago/Tarde | DY5: PtosFecha | DZ5: RSVP | EA5: Jugo | EB5: Sede | EC5: Pts | ED5: Pago/Tarde | EE5: PtosFecha | EF5: RSVP | EG5: Jugo | EH5: Sede | EI5: Pts | EJ5: Pago/Tarde | EK5: PtosFecha | EL5: RSVP | EM5: Jugo | EN5: Sede | EO5: Pts | EP5: Pago/Tarde | EQ5: PtosFecha | ER5: RSVP | ES5: Jugo | ET5: Sede | EU5: Pts | EV5: Pago/Tarde | EW5: PtosFecha | EX5: RSVP | EY5: Jugo | EZ5: Sede | FA5: Pts | FB5: Pago/Tarde | FC5: PtosFecha | FD5: RSVP | FE5: Jugo | FF5: Sede | FG5: Pts | FH5: Pago/Tarde | FI5: PtosFecha | FJ5: RSVP | FK5: Jugo | FL5: Sede | FM5: Pts | FN5: Pago/Tarde | FO5: PtosFecha | FP5: RSVP | FQ5: Jugo | FR5: Sede | FS5: Pts | FT5: Pago/Tarde | FU5: PtosFecha | FV5: RSVP | FW5: Jugo | FX5: Sede | FY5: Pts | FZ5: Pago/Tarde | GA5: PtosFecha | GB5: RSVP | GC5: Jugo | GD5: Sede | GE5: Pts | GF5: Pago/Tarde | GG5: PtosFecha | GH5: RSVP | GI5: Jugo | GJ5: Sede | GK5: Pts | GL5: Pago/Tarde | GM5: PtosFecha | GN5: RSVP | GO5: Jugo | GP5: Sede | GQ5: Pts | GR5: Pago/Tarde | GS5: PtosFecha | GT5: RSVP | GU5: Jugo | GV5: Sede | GW5: Pts | GX5: Pago/Tarde | GY5: PtosFecha | GZ5: RSVP | HA5: Jugo | HB5: Sede | HC5: Pts | HD5: Pago/Tarde | HE5: PtosFecha | HF5: RSVP | HG5: Jugo | HH5: Sede | HI5: Pts | HJ5: Pago/Tarde | HK5: PtosFecha | HL5: RSVP | HM5: Jugo | HN5: Sede | HO5: Pts | HP5: Pago/Tarde | HQ5: PtosFecha | HR5: RSVP | HS5: Jugo | HT5: Sede | HU5: Pts | HV5: Pago/Tarde | HW5: PtosFecha | HX5: RSVP | HY5: Jugo | HZ5: Sede | IA5: Pts | IB5: Pago/Tarde | IC5: PtosFecha | ID5: RSVP | IE5: Jugo | IF5: Sede | IG5: Pts | IH5: Pago/Tarde | II5: PtosFecha | IJ5: RSVP | IK5: Jugo | IL5: Sede | IM5: Pts | IN5: Pago/Tarde | IO5: PtosFecha
A6: Pato | B6: Presi | C6: =countA($A$6:A6) -> 1 | D6: =VLOOKUP(A6,TDP!A:C,3,FALSE) -> 0.54 | E6: =(1+$D6)*sum($G6,$M6,$Q6,$U6,$AA6,$AG6,$AM6,$AS6,$AY6,$BE6,$BK6,$BQ6,$BW6,$CC6,$CI6,$CO6,$CU6,$DA6,$DG6,$DM6,$DS6,$DY6,$EE6,$EK6,$EQ6,$EW6,$FC6,$FI6,$FO6,$FU6,$GA6,$GG6,$GM6,$GS6,$GY6,$HE6,$HK6,$HQ6,$HW6,$IC6,$II6,$IO6) -> 227.92 | F6: 1 | G6: =if(F6=1, 7, 0 ) -> 7 | K6: =if( H6=1, if( I6=1, if( J6=1, 5, 3), if( J6=1, 1, -3 ) ), if(I6=1,if(J6=1, -1, -2 ), if(J6=1, 7, 0 ) ) ) -> 0 | M6: =if(I6=0,K6,K6*L6) -> 0 | Q6: =if( N6=1, if( O6=1, if( P6=1, 5, 3), if( P6=1, 1, -3 ) ), if(O6=1,if(P6=1, -1, -2 ), if(P6=1, 7, 0 ) ) ) -> 0 | U6: =if( R6=1, if( S6=1, if( T6=1, 5, 3), if( T6=1, 1, -3 ) ), if(S6=1,if(T6=1, -1, -2 ), if(T6=1, 7, 0 ) ) ) -> 0 | V6: 1 | W6: 1 | X6: 1 | Y6: =if( V6=1, if( W6=1, if( X6=1, 5, 3), if( X6=1, 1, -3 ) ), if(W6=1,if(X6=1, -1, -2 ), if(X6=1, 7, 0 ) ) ) -> 5 | Z6: 1 | AA6: =if(W6=0,Y6,Y6*Z6) -> 5 | AB6: 1 | AC6: 1 | AD6: 1 | AE6: =if( AB6=1, if( AC6=1, if( AD6=1, 5, 3), if( AD6=1, 1, -3 ) ), if(AC6=1,if(AD6=1, -1, -2 ), if(AD6=1, 7, 0 ) ) ) -> 5 | AF6: 1 | AG6: =if(AC6=0,AE6,AE6*AF6) -> 5 | AH6: 1 | AI6: 1 | AJ6: 1 | AK6: =if( AH6=1, if( AI6=1, if( AJ6=1, 5, 3), if( AJ6=1, 1, -3 ) ), if(AI6=1,if(AJ6=1, -1, -2 ), if(AJ6=1, 7, 0 ) ) ) -> 5 | AL6: 1 | AM6: =if(AI6=0,AK6,AK6*AL6) -> 5 | AN6: 1 | AO6: 1 | AP6: 1 | AQ6: =if( AN6=1, if( AO6=1, if( AP6=1, 5, 3), if( AP6=1, 1, -3 ) ), if(AO6=1,if(AP6=1, -1, -2 ), if(AP6=1, 7, 0 ) ) ) -> 5 | AR6: 1 | AS6: =if(AO6=0,AQ6,AQ6*AR6) -> 5 | AT6: 1 | AU6: 1 | AV6: 1 | AW6: =if( AT6=1, if( AU6=1, if( AV6=1, 5, 3), if( AV6=1, 1, -3 ) ), if(AU6=1,if(AV6=1, -1, -2 ), if(AV6=1, 7, 0 ) ) ) -> 5 | AX6: 1 | AY6: =if(AU6=0,AW6,AW6*AX6) -> 5 | AZ6: 1 | BA6: 1 | BB6: 1 | BC6: =if( AZ6=1, if( BA6=1, if( BB6=1, 5, 3), if( BB6=1, 1, -3 ) ), if(BA6=1,if(BB6=1, -1, -2 ), if(BB6=1, 7, 0 ) ) ) -> 5 | BD6: 1 | BE6: =if(BA6=0,BC6,BC6*BD6) -> 5 | BF6: 1 | BG6: 1 | BH6: 1 | BI6: =if( BF6=1, if( BG6=1, if( BH6=1, 5, 3), if( BH6=1, 1, -3 ) ), if(BG6=1,if(BH6=1, -1, -2 ), if(BH6=1, 7, 0 ) ) ) -> 5 | BJ6: 1 | BK6: =if(BG6=0,BI6,BI6*BJ6) -> 5 | BL6: 1 | BM6: 1 | BO6: =if( BL6=1, if( BM6=1, if( BN6=1, 5, 3), if( BN6=1, 1, -3 ) ), if(BM6=1,if(BN6=1, -1, -2 ), if(BN6=1, 7, 0 ) ) ) -> 3 | BP6: 1 | BQ6: =if(BM6=0,BO6,BO6*BP6) -> 3 | BR6: 1 | BS6: 1 | BT6: 1 | BU6: =if( BR6=1, if( BS6=1, if( BT6=1, 5, 3), if( BT6=1, 1, -3 ) ), if(BS6=1,if(BT6=1, -1, -2 ), if(BT6=1, 7, 0 ) ) ) -> 5 | BV6: 1 | BW6: =if(BS6=0,BU6,BU6*BV6) -> 5 | BX6: 1 | BY6: 1 | BZ6: 1 | CA6: =if( BX6=1, if( BY6=1, if( BZ6=1, 5, 3), if( BZ6=1, 1, -3 ) ), if(BY6=1,if(BZ6=1, -1, -2 ), if(BZ6=1, 7, 0 ) ) ) -> 5 | CB6: 1 | CC6: =if(BY6=0,CA6,CA6*CB6) -> 5 | CD6: 1 | CE6: 1 | CF6: 1 | CG6: =if( CD6=1, if( CE6=1, if( CF6=1, 5, 3), if( CF6=1, 1, -3 ) ), if(CE6=1,if(CF6=1, -1, -2 ), if(CF6=1, 7, 0 ) ) ) -> 5 | CH6: 1 | CI6: =if(CE6=0,CG6,CG6*CH6) -> 5 | CJ6: 1 | CK6: 1 | CL6: 1 | CM6: =if( CJ6=1, if( CK6=1, if( CL6=1, 5, 3), if( CL6=1, 1, -3 ) ), if(CK6=1,if(CL6=1, -1, -2 ), if(CL6=1, 7, 0 ) ) ) -> 5 | CN6: 1 | CO6: =if(CK6=0,CM6,CM6*CN6) -> 5 | CP6: 1 | CQ6: 1 | CR6: 1 | CS6: =if( CP6=1, if( CQ6=1, if( CR6=1, 5, 3), if( CR6=1, 1, -3 ) ), if(CQ6=1,if(CR6=1, -1, -2 ), if(CR6=1, 7, 0 ) ) ) -> 5 | CT6: 1 | CU6: =if(CQ6=0,CS6,CS6*CT6) -> 5 | CV6: 1 | CW6: 1 | CX6: 1 | CY6: =if( CV6=1, if( CW6=1, if( CX6=1, 5, 3), if( CX6=1, 1, -3 ) ), if(CW6=1,if(CX6=1, -1, -2 ), if(CX6=1, 7, 0 ) ) ) -> 5 | CZ6: 1 | DA6: =if(CW6=0,CY6,CY6*CZ6) -> 5 | DB6: 1 | DC6: 1 | DD6: 1 | DE6: =if( DB6=1, if( DC6=1, if( DD6=1, 5, 3), if( DD6=1, 1, -3 ) ), if(DC6=1,if(DD6=1, -1, -2 ), if(DD6=1, 7, 0 ) ) ) -> 5 | DF6: 1 | DG6: =if(DC6=0,DE6,DE6*DF6) -> 5 | DH6: 1 | DI6: 1 | DJ6: 1 | DK6: =if( DH6=1, if( DI6=1, if( DJ6=1, 5, 3), if( DJ6=1, 1, -3 ) ), if(DI6=1,if(DJ6=1, -1, -2 ), if(DJ6=1, 7, 0 ) ) ) -> 5 | DL6: 1 | DM6: =if(DI6=0,DK6,DK6*DL6) -> 5 | DN6: 1 | DO6: 1 | DP6: 1 | DQ6: =if( DN6=1, if( DO6=1, if( DP6=1, 5, 3), if( DP6=1, 1, -3 ) ), if(DO6=1,if(DP6=1, -1, -2 ), if(DP6=1, 7, 0 ) ) ) -> 5 | DR6: 1 | DS6: =if(DO6=0,DQ6,DQ6*DR6) -> 5 | DT6: 1 | DU6: 1 | DV6: 1 | DW6: =if( DT6=1, if( DU6=1, if( DV6=1, 5, 3), if( DV6=1, 1, -3 ) ), if(DU6=1,if(DV6=1, -1, -2 ), if(DV6=1, 7, 0 ) ) ) -> 5 | DX6: 1 | DY6: =if(DU6=0,DW6,DW6*DX6) -> 5 | EC6: =if( DZ6=1, if( EA6=1, if( EB6=1, 5, 3), if( EB6=1, 1, -3 ) ), if(EA6=1,if(EB6=1, -1, -2 ), if(EB6=1, 7, 0 ) ) ) -> 0 | ED6: 1 | EE6: =if(EA6=0,EC6,EC6*ED6) -> 0 | EF6: 1 | EG6: 1 | EH6: 1 | EI6: =if( EF6=1, if( EG6=1, if( EH6=1, 5, 3), if( EH6=1, 1, -3 ) ), if(EG6=1,if(EH6=1, -1, -2 ), if(EH6=1, 7, 0 ) ) ) -> 5 | EJ6: 1 | EK6: =if(EG6=0,EI6,EI6*EJ6) -> 5 | EL6: 1 | EM6: 1 | EN6: 1 | EO6: =if( EL6=1, if( EM6=1, if( EN6=1, 5, 3), if( EN6=1, 1, -3 ) ), if(EM6=1,if(EN6=1, -1, -2 ), if(EN6=1, 7, 0 ) ) ) -> 5 | EP6: 1 | EQ6: =if(EM6=0,EO6,EO6*EP6) -> 5 | ER6: 1 | ES6: 1 | EU6: =if( ER6=1, if( ES6=1, if( ET6=1, 5, 3), if( ET6=1, 1, -3 ) ), if(ES6=1,if(ET6=1, -1, -2 ), if(ET6=1, 7, 0 ) ) ) -> 3 | EV6: 1 | EW6: =if(ES6=0,EU6,EU6*EV6) -> 3 | EX6: 1 | EY6: 1 | EZ6: 1 | FA6: =if( EX6=1, if( EY6=1, if( EZ6=1, 5, 3), if( EZ6=1, 1, -3 ) ), if(EY6=1,if(EZ6=1, -1, -2 ), if(EZ6=1, 7, 0 ) ) ) -> 5 | FB6: 1 | FC6: =if(EY6=0,FA6,FA6*FB6) -> 5 | FG6: =if( FD6=1, if( FE6=1, if( FF6=1, 5, 3), if( FF6=1, 1, -3 ) ), if(FE6=1,if(FF6=1, -1, -2 ), if(FF6=1, 7, 0 ) ) ) -> 0 | FH6: 1 | FI6: =if(FE6=0,FG6,FG6*FH6) -> 0 | FM6: =if( FJ6=1, if( FK6=1, if( FL6=1, 5, 3), if( FL6=1, 1, -3 ) ), if(FK6=1,if(FL6=1, -1, -2 ), if(FL6=1, 7, 0 ) ) ) -> 0 | FN6: 1 | FO6: =if(FK6=0,FM6,FM6*FN6) -> 0 | FP6: 1 | FQ6: 1 | FR6: 1 | FS6: =if( FP6=1, if( FQ6=1, if( FR6=1, 5, 3), if( FR6=1, 1, -3 ) ), if(FQ6=1,if(FR6=1, -1, -2 ), if(FR6=1, 7, 0 ) ) ) -> 5 | FT6: 1 | FU6: =if(FQ6=0,FS6,FS6*FT6) -> 5 | FV6: 1 | FW6: 1 | FX6: 1 | FY6: =if( FV6=1, if( FW6=1, if( FX6=1, 5, 3), if( FX6=1, 1, -3 ) ), if(FW6=1,if(FX6=1, -1, -2 ), if(FX6=1, 7, 0 ) ) ) -> 5 | FZ6: 1 | GA6: =if(FW6=0,FY6,FY6*FZ6) -> 5 | GB6: 1 | GC6: 1 | GD6: 1 | GE6: =if( GB6=1, if( GC6=1, if( GD6=1, 5, 3), if( GD6=1, 1, -3 ) ), if(GC6=1,if(GD6=1, -1, -2 ), if(GD6=1, 7, 0 ) ) ) -> 5 | GF6: 1 | GG6: =if(GC6=0,GE6,GE6*GF6) -> 5 | GH6: 1 | GI6: 1 | GJ6: 1 | GK6: =if( GH6=1, if( GI6=1, if( GJ6=1, 5, 3), if( GJ6=1, 1, -3 ) ), if(GI6=1,if(GJ6=1, -1, -2 ), if(GJ6=1, 7, 0 ) ) ) -> 5 | GL6: 1 | GM6: =if(GI6=0,GK6,GK6*GL6) -> 5 | GQ6: =if( GN6=1, if( GO6=1, if( GP6=1, 5, 3), if( GP6=1, 1, -3 ) ), if(GO6=1,if(GP6=1, -1, -2 ), if(GP6=1, 7, 0 ) ) ) -> 0 | GR6: 1 | GS6: =if(GO6=0,GQ6,GQ6*GR6) -> 0 | GT6: 1 | GU6: 1 | GV6: 1 | GW6: =if( GT6=1, if( GU6=1, if( GV6=1, 5, 3), if( GV6=1, 1, -3 ) ), if(GU6=1,if(GV6=1, -1, -2 ), if(GV6=1, 7, 0 ) ) ) -> 5 | GX6: 1 | GY6: =if(GU6=0,GW6,GW6*GX6) -> 5 | GZ6: 1 | HA6: 1 | HB6: 1 | HC6: =if( GZ6=1, if( HA6=1, if( HB6=1, 5, 3), if( HB6=1, 1, -3 ) ), if(HA6=1,if(HB6=1, -1, -2 ), if(HB6=1, 7, 0 ) ) ) -> 5 | HD6: 1 | HE6: =if(HA6=0,HC6,HC6*HD6) -> 5 | HF6: 1 | HG6: 1 | HH6: 1 | HI6: =if( HF6=1, if( HG6=1, if( HH6=1, 5, 3), if( HH6=1, 1, -3 ) ), if(HG6=1,if(HH6=1, -1, -2 ), if(HH6=1, 7, 0 ) ) ) -> 5 | HJ6: 1 | HK6: =if(HG6=0,HI6,HI6*HJ6) -> 5 | HO6: =if( HL6=1, if( HM6=1, if( HN6=1, 5, 3), if( HN6=1, 1, -3 ) ), if(HM6=1,if(HN6=1, -1, -2 ), if(HN6=1, 7, 0 ) ) ) -> 0 | HP6: 1 | HQ6: =if(HM6=0,HO6,HO6*HP6) -> 0 | HU6: =if( HR6=1, if( HS6=1, if( HT6=1, 5, 3), if( HT6=1, 1, -3 ) ), if(HS6=1,if(HT6=1, -1, -2 ), if(HT6=1, 7, 0 ) ) ) -> 0 | HV6: 1 | HW6: =if(HS6=0,HU6,HU6*HV6) -> 0 | IA6: =if( HX6=1, if( HY6=1, if( HZ6=1, 5, 3), if( HZ6=1, 1, -3 ) ), if(HY6=1,if(HZ6=1, -1, -2 ), if(HZ6=1, 7, 0 ) ) ) -> 0 | IB6: 1 | IC6: =if(HY6=0,IA6,IA6*IB6) -> 0 | IG6: =if( ID6=1, if( IE6=1, if( IF6=1, 5, 3), if( IF6=1, 1, -3 ) ), if(IE6=1,if(IF6=1, -1, -2 ), if(IF6=1, 7, 0 ) ) ) -> 0 | IH6: 1 | II6: =if(IE6=0,IG6,IG6*IH6) -> 0 | IM6: =if( IJ6=1, if( IK6=1, if( IL6=1, 5, 3), if( IL6=1, 1, -3 ) ), if(IK6=1,if(IL6=1, -1, -2 ), if(IL6=1, 7, 0 ) ) ) -> 0 | IN6: 1 | IO6: =if(IK6=0,IM6,IM6*IN6) -> 0
A7: Javier T | B7: No Pipita | C7: =countA($A$6:A7) -> 2 | D7: =VLOOKUP(A7,TDP!A:C,3,FALSE) -> 0.41 | E7: =(1+$D7)*sum($G7,$M7,$Q7,$U7,$AA7,$AG7,$AM7,$AS7,$AY7,$BE7,$BK7,$BQ7,$BW7,$CC7,$CI7,$CO7,$CU7,$DA7,$DG7,$DM7,$DS7,$DY7,$EE7,$EK7,$EQ7,$EW7,$FC7,$FI7,$FO7,$FU7,$GA7,$GG7,$GM7,$GS7,$GY7,$HE7,$HK7,$HQ7,$HW7,$IC7,$II7,$IO7) -> 197.4 | F7: 1 | G7: =if(F7=1, 7, 0 ) -> 7 | H7: 1 | I7: 1 | J7: 1 | K7: =if( H7=1, if( I7=1, if( J7=1, 5, 3), if( J7=1, 1, -3 ) ), if(I7=1,if(J7=1, -1, -2 ), if(J7=1, 7, 0 ) ) ) -> 5 | L7: 1 | M7: =if(I7=0,K7,K7*L7) -> 5 | Q7: =if( N7=1, if( O7=1, if( P7=1, 5, 3), if( P7=1, 1, -3 ) ), if(O7=1,if(P7=1, -1, -2 ), if(P7=1, 7, 0 ) ) ) -> 0 | U7: =if( R7=1, if( S7=1, if( T7=1, 5, 3), if( T7=1, 1, -3 ) ), if(S7=1,if(T7=1, -1, -2 ), if(T7=1, 7, 0 ) ) ) -> 0 | V7: 1 | W7: 1 | X7: 1 | Y7: =if( V7=1, if( W7=1, if( X7=1, 5, 3), if( X7=1, 1, -3 ) ), if(W7=1,if(X7=1, -1, -2 ), if(X7=1, 7, 0 ) ) ) -> 5 | Z7: 1 | AA7: =if(W7=0,Y7,Y7*Z7) -> 5 | AB7: 1 | AC7: 1 | AD7: 1 | AE7: =if( AB7=1, if( AC7=1, if( AD7=1, 5, 3), if( AD7=1, 1, -3 ) ), if(AC7=1,if(AD7=1, -1, -2 ), if(AD7=1, 7, 0 ) ) ) -> 5 | AF7: 1 | AG7: =if(AC7=0,AE7,AE7*AF7) -> 5 | AH7: 1 | AI7: 1 | AJ7: 1 | AK7: =if( AH7=1, if( AI7=1, if( AJ7=1, 5, 3), if( AJ7=1, 1, -3 ) ), if(AI7=1,if(AJ7=1, -1, -2 ), if(AJ7=1, 7, 0 ) ) ) -> 5 | AL7: 1 | AM7: =if(AI7=0,AK7,AK7*AL7) -> 5 | AN7: 1 | AO7: 1 | AP7: 1 | AQ7: =if( AN7=1, if( AO7=1, if( AP7=1, 5, 3), if( AP7=1, 1, -3 ) ), if(AO7=1,if(AP7=1, -1, -2 ), if(AP7=1, 7, 0 ) ) ) -> 5 | AR7: 1 | AS7: =if(AO7=0,AQ7,AQ7*AR7) -> 5 | AT7: 1 | AU7: 1 | AV7: 1 | AW7: =if( AT7=1, if( AU7=1, if( AV7=1, 5, 3), if( AV7=1, 1, -3 ) ), if(AU7=1,if(AV7=1, -1, -2 ), if(AV7=1, 7, 0 ) ) ) -> 5 | AX7: 1 | AY7: =if(AU7=0,AW7,AW7*AX7) -> 5 | AZ7: 1 | BA7: 1 | BB7: 1 | BC7: =if( AZ7=1, if( BA7=1, if( BB7=1, 5, 3), if( BB7=1, 1, -3 ) ), if(BA7=1,if(BB7=1, -1, -2 ), if(BB7=1, 7, 0 ) ) ) -> 5 | BD7: 1 | BE7: =if(BA7=0,BC7,BC7*BD7) -> 5 | BF7: 1 | BG7: 1 | BH7: 1 | BI7: =if( BF7=1, if( BG7=1, if( BH7=1, 5, 3), if( BH7=1, 1, -3 ) ), if(BG7=1,if(BH7=1, -1, -2 ), if(BH7=1, 7, 0 ) ) ) -> 5 | BJ7: 1 | BK7: =if(BG7=0,BI7,BI7*BJ7) -> 5 | BL7: 1 | BM7: 1 | BN7: 1 | BO7: =if( BL7=1, if( BM7=1, if( BN7=1, 5, 3), if( BN7=1, 1, -3 ) ), if(BM7=1,if(BN7=1, -1, -2 ), if(BN7=1, 7, 0 ) ) ) -> 5 | BP7: 1 | BQ7: =if(BM7=0,BO7,BO7*BP7) -> 5 | BR7: 1 | BS7: 1 | BT7: 1 | BU7: =if( BR7=1, if( BS7=1, if( BT7=1, 5, 3), if( BT7=1, 1, -3 ) ), if(BS7=1,if(BT7=1, -1, -2 ), if(BT7=1, 7, 0 ) ) ) -> 5 | BV7: 1 | BW7: =if(BS7=0,BU7,BU7*BV7) -> 5 | BX7: 1 | BY7: 1 | BZ7: 1 | CA7: =if( BX7=1, if( BY7=1, if( BZ7=1, 5, 3), if( BZ7=1, 1, -3 ) ), if(BY7=1,if(BZ7=1, -1, -2 ), if(BZ7=1, 7, 0 ) ) ) -> 5 | CB7: 1 | CC7: =if(BY7=0,CA7,CA7*CB7) -> 5 | CD7: 1 | CE7: 1 | CF7: 1 | CG7: =if( CD7=1, if( CE7=1, if( CF7=1, 5, 3), if( CF7=1, 1, -3 ) ), if(CE7=1,if(CF7=1, -1, -2 ), if(CF7=1, 7, 0 ) ) ) -> 5 | CH7: 1 | CI7: =if(CE7=0,CG7,CG7*CH7) -> 5 | CJ7: 1 | CK7: 1 | CL7: 1 | CM7: =if( CJ7=1, if( CK7=1, if( CL7=1, 5, 3), if( CL7=1, 1, -3 ) ), if(CK7=1,if(CL7=1, -1, -2 ), if(CL7=1, 7, 0 ) ) ) -> 5 | CN7: 1 | CO7: =if(CK7=0,CM7,CM7*CN7) -> 5 | CP7: 1 | CQ7: 1 | CR7: 1 | CS7: =if( CP7=1, if( CQ7=1, if( CR7=1, 5, 3), if( CR7=1, 1, -3 ) ), if(CQ7=1,if(CR7=1, -1, -2 ), if(CR7=1, 7, 0 ) ) ) -> 5 | CT7: 1 | CU7: =if(CQ7=0,CS7,CS7*CT7) -> 5 | CV7: 1 | CW7: 1 | CX7: 1 | CY7: =if( CV7=1, if( CW7=1, if( CX7=1, 5, 3), if( CX7=1, 1, -3 ) ), if(CW7=1,if(CX7=1, -1, -2 ), if(CX7=1, 7, 0 ) ) ) -> 5 | CZ7: 1 | DA7: =if(CW7=0,CY7,CY7*CZ7) -> 5 | DB7: 1 | DC7: 1 | DD7: 1 | DE7: =if( DB7=1, if( DC7=1, if( DD7=1, 5, 3), if( DD7=1, 1, -3 ) ), if(DC7=1,if(DD7=1, -1, -2 ), if(DD7=1, 7, 0 ) ) ) -> 5 | DF7: 1 | DG7: =if(DC7=0,DE7,DE7*DF7) -> 5 | DK7: =if( DH7=1, if( DI7=1, if( DJ7=1, 5, 3), if( DJ7=1, 1, -3 ) ), if(DI7=1,if(DJ7=1, -1, -2 ), if(DJ7=1, 7, 0 ) ) ) -> 0 | DM7: =if(DI7=0,DK7,DK7*DL7) -> 0 | DQ7: =if( DN7=1, if( DO7=1, if( DP7=1, 5, 3), if( DP7=1, 1, -3 ) ), if(DO7=1,if(DP7=1, -1, -2 ), if(DP7=1, 7, 0 ) ) ) -> 0 | DR7: 1 | DS7: =if(DO7=0,DQ7,DQ7*DR7) -> 0 | DW7: =if( DT7=1, if( DU7=1, if( DV7=1, 5, 3), if( DV7=1, 1, -3 ) ), if(DU7=1,if(DV7=1, -1, -2 ), if(DV7=1, 7, 0 ) ) ) -> 0 | DX7: 1 | DY7: =if(DU7=0,DW7,DW7*DX7) -> 0 | DZ7: 1 | EA7: 1 | EC7: =if( DZ7=1, if( EA7=1, if( EB7=1, 5, 3), if( EB7=1, 1, -3 ) ), if(EA7=1,if(EB7=1, -1, -2 ), if(EB7=1, 7, 0 ) ) ) -> 3 | ED7: 1 | EE7: =if(EA7=0,EC7,EC7*ED7) -> 3 | EF7: 1 | EG7: 1 | EH7: 1 | EI7: =if( EF7=1, if( EG7=1, if( EH7=1, 5, 3), if( EH7=1, 1, -3 ) ), if(EG7=1,if(EH7=1, -1, -2 ), if(EH7=1, 7, 0 ) ) ) -> 5 | EJ7: 1 | EK7: =if(EG7=0,EI7,EI7*EJ7) -> 5 | EL7: 1 | EM7: 1 | EN7: 1 | EO7: =if( EL7=1, if( EM7=1, if( EN7=1, 5, 3), if( EN7=1, 1, -3 ) ), if(EM7=1,if(EN7=1, -1, -2 ), if(EN7=1, 7, 0 ) ) ) -> 5 | EP7: 1 | EQ7: =if(EM7=0,EO7,EO7*EP7) -> 5 | ER7: 1 | ES7: 1 | ET7: 1 | EU7: =if( ER7=1, if( ES7=1, if( ET7=1, 5, 3), if( ET7=1, 1, -3 ) ), if(ES7=1,if(ET7=1, -1, -2 ), if(ET7=1, 7, 0 ) ) ) -> 5 | EV7: 1 | EW7: =if(ES7=0,EU7,EU7*EV7) -> 5 | EX7: 1 | EY7: 1 | EZ7: 1 | FA7: =if( EX7=1, if( EY7=1, if( EZ7=1, 5, 3), if( EZ7=1, 1, -3 ) ), if(EY7=1,if(EZ7=1, -1, -2 ), if(EZ7=1, 7, 0 ) ) ) -> 5 | FB7: 1 | FC7: =if(EY7=0,FA7,FA7*FB7) -> 5 | FG7: =if( FD7=1, if( FE7=1, if( FF7=1, 5, 3), if( FF7=1, 1, -3 ) ), if(FE7=1,if(FF7=1, -1, -2 ), if(FF7=1, 7, 0 ) ) ) -> 0 | FH7: 1 | FI7: =if(FE7=0,FG7,FG7*FH7) -> 0 | FM7: =if( FJ7=1, if( FK7=1, if( FL7=1, 5, 3), if( FL7=1, 1, -3 ) ), if(FK7=1,if(FL7=1, -1, -2 ), if(FL7=1, 7, 0 ) ) ) -> 0 | FN7: 1 | FO7: =if(FK7=0,FM7,FM7*FN7) -> 0 | FP7: 1 | FQ7: 1 | FR7: 1 | FS7: =if( FP7=1, if( FQ7=1, if( FR7=1, 5, 3), if( FR7=1, 1, -3 ) ), if(FQ7=1,if(FR7=1, -1, -2 ), if(FR7=1, 7, 0 ) ) ) -> 5 | FT7: 1 | FU7: =if(FQ7=0,FS7,FS7*FT7) -> 5 | FV7: 1 | FW7: 1 | FX7: 1 | FY7: =if( FV7=1, if( FW7=1, if( FX7=1, 5, 3), if( FX7=1, 1, -3 ) ), if(FW7=1,if(FX7=1, -1, -2 ), if(FX7=1, 7, 0 ) ) ) -> 5 | FZ7: 1 | GA7: =if(FW7=0,FY7,FY7*FZ7) -> 5 | GB7: 1 | GC7: 1 | GD7: 1 | GE7: =if( GB7=1, if( GC7=1, if( GD7=1, 5, 3), if( GD7=1, 1, -3 ) ), if(GC7=1,if(GD7=1, -1, -2 ), if(GD7=1, 7, 0 ) ) ) -> 5 | GF7: 1 | GG7: =if(GC7=0,GE7,GE7*GF7) -> 5 | GH7: 1 | GI7: 1 | GJ7: 1 | GK7: =if( GH7=1, if( GI7=1, if( GJ7=1, 5, 3), if( GJ7=1, 1, -3 ) ), if(GI7=1,if(GJ7=1, -1, -2 ), if(GJ7=1, 7, 0 ) ) ) -> 5 | GL7: 1 | GM7: =if(GI7=0,GK7,GK7*GL7) -> 5 | GQ7: =if( GN7=1, if( GO7=1, if( GP7=1, 5, 3), if( GP7=1, 1, -3 ) ), if(GO7=1,if(GP7=1, -1, -2 ), if(GP7=1, 7, 0 ) ) ) -> 0 | GR7: 1 | GS7: =if(GO7=0,GQ7,GQ7*GR7) -> 0 | GT7: 1 | GU7: 1 | GV7: 1 | GW7: =if( GT7=1, if( GU7=1, if( GV7=1, 5, 3), if( GV7=1, 1, -3 ) ), if(GU7=1,if(GV7=1, -1, -2 ), if(GV7=1, 7, 0 ) ) ) -> 5 | GX7: 1 | GY7: =if(GU7=0,GW7,GW7*GX7) -> 5 | HC7: =if( GZ7=1, if( HA7=1, if( HB7=1, 5, 3), if( HB7=1, 1, -3 ) ), if(HA7=1,if(HB7=1, -1, -2 ), if(HB7=1, 7, 0 ) ) ) -> 0 | HD7: 1 | HE7: =if(HA7=0,HC7,HC7*HD7) -> 0 | HF7: 1 | HG7: 1 | HH7: 1 | HI7: =if( HF7=1, if( HG7=1, if( HH7=1, 5, 3), if( HH7=1, 1, -3 ) ), if(HG7=1,if(HH7=1, -1, -2 ), if(HH7=1, 7, 0 ) ) ) -> 5 | HJ7: 1 | HK7: =if(HG7=0,HI7,HI7*HJ7) -> 5 | HO7: =if( HL7=1, if( HM7=1, if( HN7=1, 5, 3), if( HN7=1, 1, -3 ) ), if(HM7=1,if(HN7=1, -1, -2 ), if(HN7=1, 7, 0 ) ) ) -> 0 | HP7: 1 | HQ7: =if(HM7=0,HO7,HO7*HP7) -> 0 | HU7: =if( HR7=1, if( HS7=1, if( HT7=1, 5, 3), if( HT7=1, 1, -3 ) ), if(HS7=1,if(HT7=1, -1, -2 ), if(HT7=1, 7, 0 ) ) ) -> 0 | HV7: 1 | HW7: =if(HS7=0,HU7,HU7*HV7) -> 0 | IA7: =if( HX7=1, if( HY7=1, if( HZ7=1, 5, 3), if( HZ7=1, 1, -3 ) ), if(HY7=1,if(HZ7=1, -1, -2 ), if(HZ7=1, 7, 0 ) ) ) -> 0 | IB7: 1 | IC7: =if(HY7=0,IA7,IA7*IB7) -> 0 | IG7: =if( ID7=1, if( IE7=1, if( IF7=1, 5, 3), if( IF7=1, 1, -3 ) ), if(IE7=1,if(IF7=1, -1, -2 ), if(IF7=1, 7, 0 ) ) ) -> 0 | IH7: 1 | II7: =if(IE7=0,IG7,IG7*IH7) -> 0 | IM7: =if( IJ7=1, if( IK7=1, if( IL7=1, 5, 3), if( IL7=1, 1, -3 ) ), if(IK7=1,if(IL7=1, -1, -2 ), if(IL7=1, 7, 0 ) ) ) -> 0 | IN7: 1 | IO7: =if(IK7=0,IM7,IM7*IN7) -> 0
A8: Rafa | B8: Tower! | C8: =countA($A$6:A8) -> 3 | D8: =VLOOKUP(A8,TDP!A:C,3,FALSE) -> 0.56 | E8: =(1+$D8)*sum($G8,$M8,$Q8,$U8,$AA8,$AG8,$AM8,$AS8,$AY8,$BE8,$BK8,$BQ8,$BW8,$CC8,$CI8,$CO8,$CU8,$DA8,$DG8,$DM8,$DS8,$DY8,$EE8,$EK8,$EQ8,$EW8,$FC8,$FI8,$FO8,$FU8,$GA8,$GG8,$GM8,$GS8,$GY8,$HE8,$HK8,$HQ8,$HW8,$IC8,$II8,$IO8) -> 163.8 | F8: 1 | G8: =if(F8=1, 7, 0 ) -> 7 | J8: 1 | K8: =if( H8=1, if( I8=1, if( J8=1, 5, 3), if( J8=1, 1, -3 ) ), if(I8=1,if(J8=1, -1, -2 ), if(J8=1, 7, 0 ) ) ) -> 7 | M8: =if(I8=0,K8,K8*L8) -> 7 | Q8: =if( N8=1, if( O8=1, if( P8=1, 5, 3), if( P8=1, 1, -3 ) ), if(O8=1,if(P8=1, -1, -2 ), if(P8=1, 7, 0 ) ) ) -> 0 | U8: =if( R8=1, if( S8=1, if( T8=1, 5, 3), if( T8=1, 1, -3 ) ), if(S8=1,if(T8=1, -1, -2 ), if(T8=1, 7, 0 ) ) ) -> 0 | V8: 1 | W8: 1 | Y8: =if( V8=1, if( W8=1, if( X8=1, 5, 3), if( X8=1, 1, -3 ) ), if(W8=1,if(X8=1, -1, -2 ), if(X8=1, 7, 0 ) ) ) -> 3 | Z8: 1 | AA8: =if(W8=0,Y8,Y8*Z8) -> 3 | AB8: 1 | AC8: 1 | AD8: 1 | AE8: =if( AB8=1, if( AC8=1, if( AD8=1, 5, 3), if( AD8=1, 1, -3 ) ), if(AC8=1,if(AD8=1, -1, -2 ), if(AD8=1, 7, 0 ) ) ) -> 5 | AF8: 1 | AG8: =if(AC8=0,AE8,AE8*AF8) -> 5 | AK8: =if( AH8=1, if( AI8=1, if( AJ8=1, 5, 3), if( AJ8=1, 1, -3 ) ), if(AI8=1,if(AJ8=1, -1, -2 ), if(AJ8=1, 7, 0 ) ) ) -> 0 | AM8: =if(AI8=0,AK8,AK8*AL8) -> 0 | AN8: 1 | AO8: 1 | AP8: 1 | AQ8: =if( AN8=1, if( AO8=1, if( AP8=1, 5, 3), if( AP8=1, 1, -3 ) ), if(AO8=1,if(AP8=1, -1, -2 ), if(AP8=1, 7, 0 ) ) ) -> 5 | AR8: 1 | AS8: =if(AO8=0,AQ8,AQ8*AR8) -> 5 | AT8: 1 | AU8: 1 | AW8: =if( AT8=1, if( AU8=1, if( AV8=1, 5, 3), if( AV8=1, 1, -3 ) ), if(AU8=1,if(AV8=1, -1, -2 ), if(AV8=1, 7, 0 ) ) ) -> 3 | AX8: 1 | AY8: =if(AU8=0,AW8,AW8*AX8) -> 3 | AZ8: 1 | BA8: 1 | BB8: 1 | BC8: =if( AZ8=1, if( BA8=1, if( BB8=1, 5, 3), if( BB8=1, 1, -3 ) ), if(BA8=1,if(BB8=1, -1, -2 ), if(BB8=1, 7, 0 ) ) ) -> 5 | BD8: 1 | BE8: =if(BA8=0,BC8,BC8*BD8) -> 5 | BI8: =if( BF8=1, if( BG8=1, if( BH8=1, 5, 3), if( BH8=1, 1, -3 ) ), if(BG8=1,if(BH8=1, -1, -2 ), if(BH8=1, 7, 0 ) ) ) -> 0 | BK8: =if(BG8=0,BI8,BI8*BJ8) -> 0 | BL8: 1 | BM8: 1 | BO8: =if( BL8=1, if( BM8=1, if( BN8=1, 5, 3), if( BN8=1, 1, -3 ) ), if(BM8=1,if(BN8=1, -1, -2 ), if(BN8=1, 7, 0 ) ) ) -> 3 | BP8: 1 | BQ8: =if(BM8=0,BO8,BO8*BP8) -> 3 | BR8: 1 | BS8: 1 | BT8: 1 | BU8: =if( BR8=1, if( BS8=1, if( BT8=1, 5, 3), if( BT8=1, 1, -3 ) ), if(BS8=1,if(BT8=1, -1, -2 ), if(BT8=1, 7, 0 ) ) ) -> 5 | BV8: 1 | BW8: =if(BS8=0,BU8,BU8*BV8) -> 5 | BX8: 1 | BY8: 1 | BZ8: 1 | CA8: =if( BX8=1, if( BY8=1, if( BZ8=1, 5, 3), if( BZ8=1, 1, -3 ) ), if(BY8=1,if(BZ8=1, -1, -2 ), if(BZ8=1, 7, 0 ) ) ) -> 5 | CB8: 1 | CC8: =if(BY8=0,CA8,CA8*CB8) -> 5 | CG8: =if( CD8=1, if( CE8=1, if( CF8=1, 5, 3), if( CF8=1, 1, -3 ) ), if(CE8=1,if(CF8=1, -1, -2 ), if(CF8=1, 7, 0 ) ) ) -> 0 | CI8: =if(CE8=0,CG8,CG8*CH8) -> 0 | CM8: =if( CJ8=1, if( CK8=1, if( CL8=1, 5, 3), if( CL8=1, 1, -3 ) ), if(CK8=1,if(CL8=1, -1, -2 ), if(CL8=1, 7, 0 ) ) ) -> 0 | CO8: =if(CK8=0,CM8,CM8*CN8) -> 0 | CS8: =if( CP8=1, if( CQ8=1, if( CR8=1, 5, 3), if( CR8=1, 1, -3 ) ), if(CQ8=1,if(CR8=1, -1, -2 ), if(CR8=1, 7, 0 ) ) ) -> 0 | CU8: =if(CQ8=0,CS8,CS8*CT8) -> 0 | CY8: =if( CV8=1, if( CW8=1, if( CX8=1, 5, 3), if( CX8=1, 1, -3 ) ), if(CW8=1,if(CX8=1, -1, -2 ), if(CX8=1, 7, 0 ) ) ) -> 0 | CZ8: 1 | DA8: =if(CW8=0,CY8,CY8*CZ8) -> 0 | DB8: 1 | DC8: 1 | DD8: 1 | DE8: =if( DB8=1, if( DC8=1, if( DD8=1, 5, 3), if( DD8=1, 1, -3 ) ), if(DC8=1,if(DD8=1, -1, -2 ), if(DD8=1, 7, 0 ) ) ) -> 5 | DF8: 1 | DG8: =if(DC8=0,DE8,DE8*DF8) -> 5 | DH8: 1 | DI8: 1 | DK8: =if( DH8=1, if( DI8=1, if( DJ8=1, 5, 3), if( DJ8=1, 1, -3 ) ), if(DI8=1,if(DJ8=1, -1, -2 ), if(DJ8=1, 7, 0 ) ) ) -> 3 | DL8: 1 | DM8: =if(DI8=0,DK8,DK8*DL8) -> 3 | DN8: 1 | DO8: 1 | DP8: 1 | DQ8: =if( DN8=1, if( DO8=1, if( DP8=1, 5, 3), if( DP8=1, 1, -3 ) ), if(DO8=1,if(DP8=1, -1, -2 ), if(DP8=1, 7, 0 ) ) ) -> 5 | DR8: 1 | DS8: =if(DO8=0,DQ8,DQ8*DR8) -> 5 | DT8: 1 | DU8: 1 | DV8: 1 | DW8: =if( DT8=1, if( DU8=1, if( DV8=1, 5, 3), if( DV8=1, 1, -3 ) ), if(DU8=1,if(DV8=1, -1, -2 ), if(DV8=1, 7, 0 ) ) ) -> 5 | DX8: 1 | DY8: =if(DU8=0,DW8,DW8*DX8) -> 5 | EC8: =if( DZ8=1, if( EA8=1, if( EB8=1, 5, 3), if( EB8=1, 1, -3 ) ), if(EA8=1,if(EB8=1, -1, -2 ), if(EB8=1, 7, 0 ) ) ) -> 0 | ED8: 1 | EE8: =if(EA8=0,EC8,EC8*ED8) -> 0 | EF8: 1 | EG8: 1 | EH8: 1 | EI8: =if( EF8=1, if( EG8=1, if( EH8=1, 5, 3), if( EH8=1, 1, -3 ) ), if(EG8=1,if(EH8=1, -1, -2 ), if(EH8=1, 7, 0 ) ) ) -> 5 | EJ8: 1 | EK8: =if(EG8=0,EI8,EI8*EJ8) -> 5 | EO8: =if( EL8=1, if( EM8=1, if( EN8=1, 5, 3), if( EN8=1, 1, -3 ) ), if(EM8=1,if(EN8=1, -1, -2 ), if(EN8=1, 7, 0 ) ) ) -> 0 | EP8: 1 | EQ8: =if(EM8=0,EO8,EO8*EP8) -> 0 | ER8: 1 | ES8: 1 | ET8: 1 | EU8: =if( ER8=1, if( ES8=1, if( ET8=1, 5, 3), if( ET8=1, 1, -3 ) ), if(ES8=1,if(ET8=1, -1, -2 ), if(ET8=1, 7, 0 ) ) ) -> 5 | EV8: 1 | EW8: =if(ES8=0,EU8,EU8*EV8) -> 5 | FA8: =if( EX8=1, if( EY8=1, if( EZ8=1, 5, 3), if( EZ8=1, 1, -3 ) ), if(EY8=1,if(EZ8=1, -1, -2 ), if(EZ8=1, 7, 0 ) ) ) -> 0 | FB8: 1 | FC8: =if(EY8=0,FA8,FA8*FB8) -> 0 | FG8: =if( FD8=1, if( FE8=1, if( FF8=1, 5, 3), if( FF8=1, 1, -3 ) ), if(FE8=1,if(FF8=1, -1, -2 ), if(FF8=1, 7, 0 ) ) ) -> 0 | FH8: 1 | FI8: =if(FE8=0,FG8,FG8*FH8) -> 0 | FM8: =if( FJ8=1, if( FK8=1, if( FL8=1, 5, 3), if( FL8=1, 1, -3 ) ), if(FK8=1,if(FL8=1, -1, -2 ), if(FL8=1, 7, 0 ) ) ) -> 0 | FN8: 1 | FO8: =if(FK8=0,FM8,FM8*FN8) -> 0 | FP8: 1 | FQ8: 1 | FS8: =if( FP8=1, if( FQ8=1, if( FR8=1, 5, 3), if( FR8=1, 1, -3 ) ), if(FQ8=1,if(FR8=1, -1, -2 ), if(FR8=1, 7, 0 ) ) ) -> 3 | FT8: 1 | FU8: =if(FQ8=0,FS8,FS8*FT8) -> 3 | FV8: 1 | FW8: 1 | FY8: =if( FV8=1, if( FW8=1, if( FX8=1, 5, 3), if( FX8=1, 1, -3 ) ), if(FW8=1,if(FX8=1, -1, -2 ), if(FX8=1, 7, 0 ) ) ) -> 3 | FZ8: 1 | GA8: =if(FW8=0,FY8,FY8*FZ8) -> 3 | GB8: 1 | GC8: 1 | GE8: =if( GB8=1, if( GC8=1, if( GD8=1, 5, 3), if( GD8=1, 1, -3 ) ), if(GC8=1,if(GD8=1, -1, -2 ), if(GD8=1, 7, 0 ) ) ) -> 3 | GF8: 1 | GG8: =if(GC8=0,GE8,GE8*GF8) -> 3 | GH8: 1 | GI8: 1 | GJ8: 1 | GK8: =if( GH8=1, if( GI8=1, if( GJ8=1, 5, 3), if( GJ8=1, 1, -3 ) ), if(GI8=1,if(GJ8=1, -1, -2 ), if(GJ8=1, 7, 0 ) ) ) -> 5 | GL8: 1 | GM8: =if(GI8=0,GK8,GK8*GL8) -> 5 | GQ8: =if( GN8=1, if( GO8=1, if( GP8=1, 5, 3), if( GP8=1, 1, -3 ) ), if(GO8=1,if(GP8=1, -1, -2 ), if(GP8=1, 7, 0 ) ) ) -> 0 | GR8: 1 | GS8: =if(GO8=0,GQ8,GQ8*GR8) -> 0 | GT8: 1 | GU8: 1 | GV8: 1 | GW8: =if( GT8=1, if( GU8=1, if( GV8=1, 5, 3), if( GV8=1, 1, -3 ) ), if(GU8=1,if(GV8=1, -1, -2 ), if(GV8=1, 7, 0 ) ) ) -> 5 | GX8: 1 | GY8: =if(GU8=0,GW8,GW8*GX8) -> 5 | GZ8: 1 | HA8: 1 | HB8: 1 | HC8: =if( GZ8=1, if( HA8=1, if( HB8=1, 5, 3), if( HB8=1, 1, -3 ) ), if(HA8=1,if(HB8=1, -1, -2 ), if(HB8=1, 7, 0 ) ) ) -> 5 | HD8: 1 | HE8: =if(HA8=0,HC8,HC8*HD8) -> 5 | HF8: 1 | HG8: 1 | HH8: 1 | HI8: =if( HF8=1, if( HG8=1, if( HH8=1, 5, 3), if( HH8=1, 1, -3 ) ), if(HG8=1,if(HH8=1, -1, -2 ), if(HH8=1, 7, 0 ) ) ) -> 5 | HJ8: 1 | HK8: =if(HG8=0,HI8,HI8*HJ8) -> 5 | HO8: =if( HL8=1, if( HM8=1, if( HN8=1, 5, 3), if( HN8=1, 1, -3 ) ), if(HM8=1,if(HN8=1, -1, -2 ), if(HN8=1, 7, 0 ) ) ) -> 0 | HP8: 1 | HQ8: =if(HM8=0,HO8,HO8*HP8) -> 0 | HU8: =if( HR8=1, if( HS8=1, if( HT8=1, 5, 3), if( HT8=1, 1, -3 ) ), if(HS8=1,if(HT8=1, -1, -2 ), if(HT8=1, 7, 0 ) ) ) -> 0 | HV8: 1 | HW8: =if(HS8=0,HU8,HU8*HV8) -> 0 | IA8: =if( HX8=1, if( HY8=1, if( HZ8=1, 5, 3), if( HZ8=1, 1, -3 ) ), if(HY8=1,if(HZ8=1, -1, -2 ), if(HZ8=1, 7, 0 ) ) ) -> 0 | IB8: 1 | IC8: =if(HY8=0,IA8,IA8*IB8) -> 0 | IG8: =if( ID8=1, if( IE8=1, if( IF8=1, 5, 3), if( IF8=1, 1, -3 ) ), if(IE8=1,if(IF8=1, -1, -2 ), if(IF8=1, 7, 0 ) ) ) -> 0 | IH8: 1 | II8: =if(IE8=0,IG8,IG8*IH8) -> 0 | IM8: =if( IJ8=1, if( IK8=1, if( IL8=1, 5, 3), if( IL8=1, 1, -3 ) ), if(IK8=1,if(IL8=1, -1, -2 ), if(IL8=1, 7, 0 ) ) ) -> 0 | IN8: 1 | IO8: =if(IK8=0,IM8,IM8*IN8) -> 0
A9: Nico | B9: Goomba | C9: =countA($A$6:A9) -> 4 | D9: =VLOOKUP(A9,TDP!A:C,3,FALSE) -> 0.27 | E9: =(1+$D9)*sum($G9,$M9,$Q9,$U9,$AA9,$AG9,$AM9,$AS9,$AY9,$BE9,$BK9,$BQ9,$BW9,$CC9,$CI9,$CO9,$CU9,$DA9,$DG9,$DM9,$DS9,$DY9,$EE9,$EK9,$EQ9,$EW9,$FC9,$FI9,$FO9,$FU9,$GA9,$GG9,$GM9,$GS9,$GY9,$HE9,$HK9,$HQ9,$HW9,$IC9,$II9,$IO9) -> 161.29 | F9: 1 | G9: =if(F9=1, 7, 0 ) -> 7 | H9: 1 | I9: 1 | J9: 1 | K9: =if( H9=1, if( I9=1, if( J9=1, 5, 3), if( J9=1, 1, -3 ) ), if(I9=1,if(J9=1, -1, -2 ), if(J9=1, 7, 0 ) ) ) -> 5 | M9: =if(I9=0,K9,K9*L9) -> 0 | Q9: =if( N9=1, if( O9=1, if( P9=1, 5, 3), if( P9=1, 1, -3 ) ), if(O9=1,if(P9=1, -1, -2 ), if(P9=1, 7, 0 ) ) ) -> 0 | U9: =if( R9=1, if( S9=1, if( T9=1, 5, 3), if( T9=1, 1, -3 ) ), if(S9=1,if(T9=1, -1, -2 ), if(T9=1, 7, 0 ) ) ) -> 0 | X9: 1 | Y9: =if( V9=1, if( W9=1, if( X9=1, 5, 3), if( X9=1, 1, -3 ) ), if(W9=1,if(X9=1, -1, -2 ), if(X9=1, 7, 0 ) ) ) -> 7 | AA9: =if(W9=0,Y9,Y9*Z9) -> 7 | AD9: 1 | AE9: =if( AB9=1, if( AC9=1, if( AD9=1, 5, 3), if( AD9=1, 1, -3 ) ), if(AC9=1,if(AD9=1, -1, -2 ), if(AD9=1, 7, 0 ) ) ) -> 7 | AG9: =if(AC9=0,AE9,AE9*AF9) -> 7 | AJ9: 1 | AK9: =if( AH9=1, if( AI9=1, if( AJ9=1, 5, 3), if( AJ9=1, 1, -3 ) ), if(AI9=1,if(AJ9=1, -1, -2 ), if(AJ9=1, 7, 0 ) ) ) -> 7 | AM9: =if(AI9=0,AK9,AK9*AL9) -> 7 | AQ9: =if( AN9=1, if( AO9=1, if( AP9=1, 5, 3), if( AP9=1, 1, -3 ) ), if(AO9=1,if(AP9=1, -1, -2 ), if(AP9=1, 7, 0 ) ) ) -> 0 | AS9: =if(AO9=0,AQ9,AQ9*AR9) -> 0 | AV9: 1 | AW9: =if( AT9=1, if( AU9=1, if( AV9=1, 5, 3), if( AV9=1, 1, -3 ) ), if(AU9=1,if(AV9=1, -1, -2 ), if(AV9=1, 7, 0 ) ) ) -> 7 | AY9: =if(AU9=0,AW9,AW9*AX9) -> 7 | BC9: =if( AZ9=1, if( BA9=1, if( BB9=1, 5, 3), if( BB9=1, 1, -3 ) ), if(BA9=1,if(BB9=1, -1, -2 ), if(BB9=1, 7, 0 ) ) ) -> 0 | BE9: =if(BA9=0,BC9,BC9*BD9) -> 0 | BH9: 1 | BI9: =if( BF9=1, if( BG9=1, if( BH9=1, 5, 3), if( BH9=1, 1, -3 ) ), if(BG9=1,if(BH9=1, -1, -2 ), if(BH9=1, 7, 0 ) ) ) -> 7 | BK9: =if(BG9=0,BI9,BI9*BJ9) -> 7 | BN9: 1 | BO9: =if( BL9=1, if( BM9=1, if( BN9=1, 5, 3), if( BN9=1, 1, -3 ) ), if(BM9=1,if(BN9=1, -1, -2 ), if(BN9=1, 7, 0 ) ) ) -> 7 | BQ9: =if(BM9=0,BO9,BO9*BP9) -> 7 | BU9: =if( BR9=1, if( BS9=1, if( BT9=1, 5, 3), if( BT9=1, 1, -3 ) ), if(BS9=1,if(BT9=1, -1, -2 ), if(BT9=1, 7, 0 ) ) ) -> 0 | BW9: =if(BS9=0,BU9,BU9*BV9) -> 0 | CA9: =if( BX9=1, if( BY9=1, if( BZ9=1, 5, 3), if( BZ9=1, 1, -3 ) ), if(BY9=1,if(BZ9=1, -1, -2 ), if(BZ9=1, 7, 0 ) ) ) -> 0 | CC9: =if(BY9=0,CA9,CA9*CB9) -> 0 | CD9: 1 | CE9: 1 | CF9: 1 | CG9: =if( CD9=1, if( CE9=1, if( CF9=1, 5, 3), if( CF9=1, 1, -3 ) ), if(CE9=1,if(CF9=1, -1, -2 ), if(CF9=1, 7, 0 ) ) ) -> 5 | CH9: 1 | CI9: =if(CE9=0,CG9,CG9*CH9) -> 5 | CJ9: 1 | CK9: 1 | CL9: 1 | CM9: =if( CJ9=1, if( CK9=1, if( CL9=1, 5, 3), if( CL9=1, 1, -3 ) ), if(CK9=1,if(CL9=1, -1, -2 ), if(CL9=1, 7, 0 ) ) ) -> 5 | CN9: 1 | CO9: =if(CK9=0,CM9,CM9*CN9) -> 5 | CS9: =if( CP9=1, if( CQ9=1, if( CR9=1, 5, 3), if( CR9=1, 1, -3 ) ), if(CQ9=1,if(CR9=1, -1, -2 ), if(CR9=1, 7, 0 ) ) ) -> 0 | CU9: =if(CQ9=0,CS9,CS9*CT9) -> 0 | CV9: 1 | CW9: 1 | CX9: 1 | CY9: =if( CV9=1, if( CW9=1, if( CX9=1, 5, 3), if( CX9=1, 1, -3 ) ), if(CW9=1,if(CX9=1, -1, -2 ), if(CX9=1, 7, 0 ) ) ) -> 5 | CZ9: 1 | DA9: =if(CW9=0,CY9,CY9*CZ9) -> 5 | DB9: 1 | DC9: 1 | DD9: 1 | DE9: =if( DB9=1, if( DC9=1, if( DD9=1, 5, 3), if( DD9=1, 1, -3 ) ), if(DC9=1,if(DD9=1, -1, -2 ), if(DD9=1, 7, 0 ) ) ) -> 5 | DF9: 1 | DG9: =if(DC9=0,DE9,DE9*DF9) -> 5 | DH9: 1 | DI9: 1 | DJ9: 1 | DK9: =if( DH9=1, if( DI9=1, if( DJ9=1, 5, 3), if( DJ9=1, 1, -3 ) ), if(DI9=1,if(DJ9=1, -1, -2 ), if(DJ9=1, 7, 0 ) ) ) -> 5 | DL9: 1 | DM9: =if(DI9=0,DK9,DK9*DL9) -> 5 | DN9: 1 | DO9: 1 | DP9: 1 | DQ9: =if( DN9=1, if( DO9=1, if( DP9=1, 5, 3), if( DP9=1, 1, -3 ) ), if(DO9=1,if(DP9=1, -1, -2 ), if(DP9=1, 7, 0 ) ) ) -> 5 | DR9: 1 | DS9: =if(DO9=0,DQ9,DQ9*DR9) -> 5 | DT9: 1 | DU9: 1 | DV9: 1 | DW9: =if( DT9=1, if( DU9=1, if( DV9=1, 5, 3), if( DV9=1, 1, -3 ) ), if(DU9=1,if(DV9=1, -1, -2 ), if(DV9=1, 7, 0 ) ) ) -> 5 | DX9: 1 | DY9: =if(DU9=0,DW9,DW9*DX9) -> 5 | EC9: =if( DZ9=1, if( EA9=1, if( EB9=1, 5, 3), if( EB9=1, 1, -3 ) ), if(EA9=1,if(EB9=1, -1, -2 ), if(EB9=1, 7, 0 ) ) ) -> 0 | ED9: 1 | EE9: =if(EA9=0,EC9,EC9*ED9) -> 0 | EF9: 1 | EG9: 1 | EH9: 1 | EI9: =if( EF9=1, if( EG9=1, if( EH9=1, 5, 3), if( EH9=1, 1, -3 ) ), if(EG9=1,if(EH9=1, -1, -2 ), if(EH9=1, 7, 0 ) ) ) -> 5 | EJ9: 1 | EK9: =if(EG9=0,EI9,EI9*EJ9) -> 5 | EL9: 1 | EM9: 1 | EN9: 1 | EO9: =if( EL9=1, if( EM9=1, if( EN9=1, 5, 3), if( EN9=1, 1, -3 ) ), if(EM9=1,if(EN9=1, -1, -2 ), if(EN9=1, 7, 0 ) ) ) -> 5 | EP9: 1 | EQ9: =if(EM9=0,EO9,EO9*EP9) -> 5 | ER9: 1 | ES9: 1 | ET9: 1 | EU9: =if( ER9=1, if( ES9=1, if( ET9=1, 5, 3), if( ET9=1, 1, -3 ) ), if(ES9=1,if(ET9=1, -1, -2 ), if(ET9=1, 7, 0 ) ) ) -> 5 | EV9: 1 | EW9: =if(ES9=0,EU9,EU9*EV9) -> 5 | EX9: 1 | EY9: 1 | EZ9: 1 | FA9: =if( EX9=1, if( EY9=1, if( EZ9=1, 5, 3), if( EZ9=1, 1, -3 ) ), if(EY9=1,if(EZ9=1, -1, -2 ), if(EZ9=1, 7, 0 ) ) ) -> 5 | FB9: 1 | FC9: =if(EY9=0,FA9,FA9*FB9) -> 5 | FG9: =if( FD9=1, if( FE9=1, if( FF9=1, 5, 3), if( FF9=1, 1, -3 ) ), if(FE9=1,if(FF9=1, -1, -2 ), if(FF9=1, 7, 0 ) ) ) -> 0 | FH9: 1 | FI9: =if(FE9=0,FG9,FG9*FH9) -> 0 | FM9: =if( FJ9=1, if( FK9=1, if( FL9=1, 5, 3), if( FL9=1, 1, -3 ) ), if(FK9=1,if(FL9=1, -1, -2 ), if(FL9=1, 7, 0 ) ) ) -> 0 | FN9: 1 | FO9: =if(FK9=0,FM9,FM9*FN9) -> 0 | FP9: 1 | FQ9: 1 | FR9: 1 | FS9: =if( FP9=1, if( FQ9=1, if( FR9=1, 5, 3), if( FR9=1, 1, -3 ) ), if(FQ9=1,if(FR9=1, -1, -2 ), if(FR9=1, 7, 0 ) ) ) -> 5 | FT9: 1 | FU9: =if(FQ9=0,FS9,FS9*FT9) -> 5 | FV9: 1 | FW9: 1 | FX9: 1 | FY9: =if( FV9=1, if( FW9=1, if( FX9=1, 5, 3), if( FX9=1, 1, -3 ) ), if(FW9=1,if(FX9=1, -1, -2 ), if(FX9=1, 7, 0 ) ) ) -> 5 | FZ9: 1 | GA9: =if(FW9=0,FY9,FY9*FZ9) -> 5 | GB9: 1 | GC9: 1 | GE9: =if( GB9=1, if( GC9=1, if( GD9=1, 5, 3), if( GD9=1, 1, -3 ) ), if(GC9=1,if(GD9=1, -1, -2 ), if(GD9=1, 7, 0 ) ) ) -> 3 | GF9: 1 | GG9: =if(GC9=0,GE9,GE9*GF9) -> 3 | GH9: 1 | GI9: 1 | GJ9: 1 | GK9: =if( GH9=1, if( GI9=1, if( GJ9=1, 5, 3), if( GJ9=1, 1, -3 ) ), if(GI9=1,if(GJ9=1, -1, -2 ), if(GJ9=1, 7, 0 ) ) ) -> 5 | GL9: 1 | GM9: =if(GI9=0,GK9,GK9*GL9) -> 5 | GQ9: =if( GN9=1, if( GO9=1, if( GP9=1, 5, 3), if( GP9=1, 1, -3 ) ), if(GO9=1,if(GP9=1, -1, -2 ), if(GP9=1, 7, 0 ) ) ) -> 0 | GR9: 1 | GS9: =if(GO9=0,GQ9,GQ9*GR9) -> 0 | GT9: 1 | GU9: 1 | GV9: 1 | GW9: =if( GT9=1, if( GU9=1, if( GV9=1, 5, 3), if( GV9=1, 1, -3 ) ), if(GU9=1,if(GV9=1, -1, -2 ), if(GV9=1, 7, 0 ) ) ) -> 5 | GX9: 1 | GY9: =if(GU9=0,GW9,GW9*GX9) -> 5 | HC9: =if( GZ9=1, if( HA9=1, if( HB9=1, 5, 3), if( HB9=1, 1, -3 ) ), if(HA9=1,if(HB9=1, -1, -2 ), if(HB9=1, 7, 0 ) ) ) -> 0 | HD9: 1 | HE9: =if(HA9=0,HC9,HC9*HD9) -> 0 | HI9: =if( HF9=1, if( HG9=1, if( HH9=1, 5, 3), if( HH9=1, 1, -3 ) ), if(HG9=1,if(HH9=1, -1, -2 ), if(HH9=1, 7, 0 ) ) ) -> 0 | HJ9: 1 | HK9: =if(HG9=0,HI9,HI9*HJ9) -> 0 | HO9: =if( HL9=1, if( HM9=1, if( HN9=1, 5, 3), if( HN9=1, 1, -3 ) ), if(HM9=1,if(HN9=1, -1, -2 ), if(HN9=1, 7, 0 ) ) ) -> 0 | HP9: 1 | HQ9: =if(HM9=0,HO9,HO9*HP9) -> 0 | HU9: =if( HR9=1, if( HS9=1, if( HT9=1, 5, 3), if( HT9=1, 1, -3 ) ), if(HS9=1,if(HT9=1, -1, -2 ), if(HT9=1, 7, 0 ) ) ) -> 0 | HV9: 1 | HW9: =if(HS9=0,HU9,HU9*HV9) -> 0 | IA9: =if( HX9=1, if( HY9=1, if( HZ9=1, 5, 3), if( HZ9=1, 1, -3 ) ), if(HY9=1,if(HZ9=1, -1, -2 ), if(HZ9=1, 7, 0 ) ) ) -> 0 | IB9: 1 | IC9: =if(HY9=0,IA9,IA9*IB9) -> 0 | IG9: =if( ID9=1, if( IE9=1, if( IF9=1, 5, 3), if( IF9=1, 1, -3 ) ), if(IE9=1,if(IF9=1, -1, -2 ), if(IF9=1, 7, 0 ) ) ) -> 0 | IH9: 1 | II9: =if(IE9=0,IG9,IG9*IH9) -> 0 | IM9: =if( IJ9=1, if( IK9=1, if( IL9=1, 5, 3), if( IL9=1, 1, -3 ) ), if(IK9=1,if(IL9=1, -1, -2 ), if(IL9=1, 7, 0 ) ) ) -> 0 | IN9: 1 | IO9: =if(IK9=0,IM9,IM9*IN9) -> 0
A10: Michael G | B10: Curly | C10: =countA($A$6:A10) -> 5 | D10: =VLOOKUP(A10,TDP!A:C,3,FALSE) -> 0.51 | E10: =(1+$D10)*sum($G10,$M10,$Q10,$U10,$AA10,$AG10,$AM10,$AS10,$AY10,$BE10,$BK10,$BQ10,$BW10,$CC10,$CI10,$CO10,$CU10,$DA10,$DG10,$DM10,$DS10,$DY10,$EE10,$EK10,$EQ10,$EW10,$FC10,$FI10,$FO10,$FU10,$GA10,$GG10,$GM10,$GS10,$GY10,$HE10,$HK10,$HQ10,$HW10,$IC10,$II10,$IO10) -> 154.02 | G10: =if(F10=1, 7, 0 ) -> 0 | H10: 1 | I10: 1 | J10: 1 | K10: =if( H10=1, if( I10=1, if( J10=1, 5, 3), if( J10=1, 1, -3 ) ), if(I10=1,if(J10=1, -1, -2 ), if(J10=1, 7, 0 ) ) ) -> 5 | L10: 1 | M10: =if(I10=0,K10,K10*L10) -> 5 | Q10: =if( N10=1, if( O10=1, if( P10=1, 5, 3), if( P10=1, 1, -3 ) ), if(O10=1,if(P10=1, -1, -2 ), if(P10=1, 7, 0 ) ) ) -> 0 | U10: =if( R10=1, if( S10=1, if( T10=1, 5, 3), if( T10=1, 1, -3 ) ), if(S10=1,if(T10=1, -1, -2 ), if(T10=1, 7, 0 ) ) ) -> 0 | V10: 1 | W10: 1 | Y10: =if( V10=1, if( W10=1, if( X10=1, 5, 3), if( X10=1, 1, -3 ) ), if(W10=1,if(X10=1, -1, -2 ), if(X10=1, 7, 0 ) ) ) -> 3 | Z10: 1 | AA10: =if(W10=0,Y10,Y10*Z10) -> 3 | AE10: =if( AB10=1, if( AC10=1, if( AD10=1, 5, 3), if( AD10=1, 1, -3 ) ), if(AC10=1,if(AD10=1, -1, -2 ), if(AD10=1, 7, 0 ) ) ) -> 0 | AG10: =if(AC10=0,AE10,AE10*AF10) -> 0 | AH10: 1 | AI10: 1 | AK10: =if( AH10=1, if( AI10=1, if( AJ10=1, 5, 3), if( AJ10=1, 1, -3 ) ), if(AI10=1,if(AJ10=1, -1, -2 ), if(AJ10=1, 7, 0 ) ) ) -> 3 | AL10: 1 | AM10: =if(AI10=0,AK10,AK10*AL10) -> 3 | AN10: 1 | AO10: 1 | AP10: 1 | AQ10: =if( AN10=1, if( AO10=1, if( AP10=1, 5, 3), if( AP10=1, 1, -3 ) ), if(AO10=1,if(AP10=1, -1, -2 ), if(AP10=1, 7, 0 ) ) ) -> 5 | AR10: 1 | AS10: =if(AO10=0,AQ10,AQ10*AR10) -> 5 | AT10: 1 | AU10: 1 | AV10: 1 | AW10: =if( AT10=1, if( AU10=1, if( AV10=1, 5, 3), if( AV10=1, 1, -3 ) ), if(AU10=1,if(AV10=1, -1, -2 ), if(AV10=1, 7, 0 ) ) ) -> 5 | AX10: 1 | AY10: =if(AU10=0,AW10,AW10*AX10) -> 5 | AZ10: 1 | BA10: 1 | BB10: 1 | BC10: =if( AZ10=1, if( BA10=1, if( BB10=1, 5, 3), if( BB10=1, 1, -3 ) ), if(BA10=1,if(BB10=1, -1, -2 ), if(BB10=1, 7, 0 ) ) ) -> 5 | BD10: 1 | BE10: =if(BA10=0,BC10,BC10*BD10) -> 5 | BF10: 1 | BG10: 1 | BH10: 1 | BI10: =if( BF10=1, if( BG10=1, if( BH10=1, 5, 3), if( BH10=1, 1, -3 ) ), if(BG10=1,if(BH10=1, -1, -2 ), if(BH10=1, 7, 0 ) ) ) -> 5 | BJ10: 1 | BK10: =if(BG10=0,BI10,BI10*BJ10) -> 5 | BL10: 1 | BM10: 1 | BN10: 1 | BO10: =if( BL10=1, if( BM10=1, if( BN10=1, 5, 3), if( BN10=1, 1, -3 ) ), if(BM10=1,if(BN10=1, -1, -2 ), if(BN10=1, 7, 0 ) ) ) -> 5 | BP10: 1 | BQ10: =if(BM10=0,BO10,BO10*BP10) -> 5 | BR10: 1 | BS10: 1 | BT10: 1 | BU10: =if( BR10=1, if( BS10=1, if( BT10=1, 5, 3), if( BT10=1, 1, -3 ) ), if(BS10=1,if(BT10=1, -1, -2 ), if(BT10=1, 7, 0 ) ) ) -> 5 | BV10: 1 | BW10: =if(BS10=0,BU10,BU10*BV10) -> 5 | CA10: =if( BX10=1, if( BY10=1, if( BZ10=1, 5, 3), if( BZ10=1, 1, -3 ) ), if(BY10=1,if(BZ10=1, -1, -2 ), if(BZ10=1, 7, 0 ) ) ) -> 0 | CC10: =if(BY10=0,CA10,CA10*CB10) -> 0 | CD10: 1 | CE10: 1 | CF10: 1 | CG10: =if( CD10=1, if( CE10=1, if( CF10=1, 5, 3), if( CF10=1, 1, -3 ) ), if(CE10=1,if(CF10=1, -1, -2 ), if(CF10=1, 7, 0 ) ) ) -> 5 | CH10: 1 | CI10: =if(CE10=0,CG10,CG10*CH10) -> 5 | CM10: =if( CJ10=1, if( CK10=1, if( CL10=1, 5, 3), if( CL10=1, 1, -3 ) ), if(CK10=1,if(CL10=1, -1, -2 ), if(CL10=1, 7, 0 ) ) ) -> 0 | CO10: =if(CK10=0,CM10,CM10*CN10) -> 0 | CP10: 1 | CQ10: 1 | CR10: 1 | CS10: =if( CP10=1, if( CQ10=1, if( CR10=1, 5, 3), if( CR10=1, 1, -3 ) ), if(CQ10=1,if(CR10=1, -1, -2 ), if(CR10=1, 7, 0 ) ) ) -> 5 | CT10: 1 | CU10: =if(CQ10=0,CS10,CS10*CT10) -> 5 | CV10: 1 | CW10: 1 | CX10: 1 | CY10: =if( CV10=1, if( CW10=1, if( CX10=1, 5, 3), if( CX10=1, 1, -3 ) ), if(CW10=1,if(CX10=1, -1, -2 ), if(CX10=1, 7, 0 ) ) ) -> 5 | CZ10: 1 | DA10: =if(CW10=0,CY10,CY10*CZ10) -> 5 | DB10: 1 | DC10: 1 | DD10: 1 | DE10: =if( DB10=1, if( DC10=1, if( DD10=1, 5, 3), if( DD10=1, 1, -3 ) ), if(DC10=1,if(DD10=1, -1, -2 ), if(DD10=1, 7, 0 ) ) ) -> 5 | DF10: 1 | DG10: =if(DC10=0,DE10,DE10*DF10) -> 5 | DH10: 1 | DI10: 1 | DJ10: 1 | DK10: =if( DH10=1, if( DI10=1, if( DJ10=1, 5, 3), if( DJ10=1, 1, -3 ) ), if(DI10=1,if(DJ10=1, -1, -2 ), if(DJ10=1, 7, 0 ) ) ) -> 5 | DL10: 1 | DM10: =if(DI10=0,DK10,DK10*DL10) -> 5 | DQ10: =if( DN10=1, if( DO10=1, if( DP10=1, 5, 3), if( DP10=1, 1, -3 ) ), if(DO10=1,if(DP10=1, -1, -2 ), if(DP10=1, 7, 0 ) ) ) -> 0 | DR10: 1 | DS10: =if(DO10=0,DQ10,DQ10*DR10) -> 0 | DW10: =if( DT10=1, if( DU10=1, if( DV10=1, 5, 3), if( DV10=1, 1, -3 ) ), if(DU10=1,if(DV10=1, -1, -2 ), if(DV10=1, 7, 0 ) ) ) -> 0 | DX10: 1 | DY10: =if(DU10=0,DW10,DW10*DX10) -> 0 | DZ10: 1 | EA10: 1 | EC10: =if( DZ10=1, if( EA10=1, if( EB10=1, 5, 3), if( EB10=1, 1, -3 ) ), if(EA10=1,if(EB10=1, -1, -2 ), if(EB10=1, 7, 0 ) ) ) -> 3 | ED10: 1 | EE10: =if(EA10=0,EC10,EC10*ED10) -> 3 | EF10: 1 | EG10: 1 | EH10: 1 | EI10: =if( EF10=1, if( EG10=1, if( EH10=1, 5, 3), if( EH10=1, 1, -3 ) ), if(EG10=1,if(EH10=1, -1, -2 ), if(EH10=1, 7, 0 ) ) ) -> 5 | EJ10: 1 | EK10: =if(EG10=0,EI10,EI10*EJ10) -> 5 | EL10: 1 | EM10: 1 | EN10: 1 | EO10: =if( EL10=1, if( EM10=1, if( EN10=1, 5, 3), if( EN10=1, 1, -3 ) ), if(EM10=1,if(EN10=1, -1, -2 ), if(EN10=1, 7, 0 ) ) ) -> 5 | EP10: 1 | EQ10: =if(EM10=0,EO10,EO10*EP10) -> 5 | ER10: 1 | ES10: 1 | ET10: 1 | EU10: =if( ER10=1, if( ES10=1, if( ET10=1, 5, 3), if( ET10=1, 1, -3 ) ), if(ES10=1,if(ET10=1, -1, -2 ), if(ET10=1, 7, 0 ) ) ) -> 5 | EV10: 1 | EW10: =if(ES10=0,EU10,EU10*EV10) -> 5 | EX10: 1 | EY10: 1 | EZ10: 1 | FA10: =if( EX10=1, if( EY10=1, if( EZ10=1, 5, 3), if( EZ10=1, 1, -3 ) ), if(EY10=1,if(EZ10=1, -1, -2 ), if(EZ10=1, 7, 0 ) ) ) -> 5 | FB10: 1 | FC10: =if(EY10=0,FA10,FA10*FB10) -> 5 | FG10: =if( FD10=1, if( FE10=1, if( FF10=1, 5, 3), if( FF10=1, 1, -3 ) ), if(FE10=1,if(FF10=1, -1, -2 ), if(FF10=1, 7, 0 ) ) ) -> 0 | FH10: 1 | FI10: =if(FE10=0,FG10,FG10*FH10) -> 0 | FM10: =if( FJ10=1, if( FK10=1, if( FL10=1, 5, 3), if( FL10=1, 1, -3 ) ), if(FK10=1,if(FL10=1, -1, -2 ), if(FL10=1, 7, 0 ) ) ) -> 0 | FN10: 1 | FO10: =if(FK10=0,FM10,FM10*FN10) -> 0 | FP10: 1 | FQ10: 1 | FR10: 1 | FS10: =if( FP10=1, if( FQ10=1, if( FR10=1, 5, 3), if( FR10=1, 1, -3 ) ), if(FQ10=1,if(FR10=1, -1, -2 ), if(FR10=1, 7, 0 ) ) ) -> 5 | FT10: 1 | FU10: =if(FQ10=0,FS10,FS10*FT10) -> 5 | FV10: 1 | FW10: 1 | FY10: =if( FV10=1, if( FW10=1, if( FX10=1, 5, 3), if( FX10=1, 1, -3 ) ), if(FW10=1,if(FX10=1, -1, -2 ), if(FX10=1, 7, 0 ) ) ) -> 3 | FZ10: 1 | GA10: =if(FW10=0,FY10,FY10*FZ10) -> 3 | GE10: =if( GB10=1, if( GC10=1, if( GD10=1, 5, 3), if( GD10=1, 1, -3 ) ), if(GC10=1,if(GD10=1, -1, -2 ), if(GD10=1, 7, 0 ) ) ) -> 0 | GF10: 1 | GG10: =if(GC10=0,GE10,GE10*GF10) -> 0 | GK10: =if( GH10=1, if( GI10=1, if( GJ10=1, 5, 3), if( GJ10=1, 1, -3 ) ), if(GI10=1,if(GJ10=1, -1, -2 ), if(GJ10=1, 7, 0 ) ) ) -> 0 | GL10: 1 | GM10: =if(GI10=0,GK10,GK10*GL10) -> 0 | GQ10: =if( GN10=1, if( GO10=1, if( GP10=1, 5, 3), if( GP10=1, 1, -3 ) ), if(GO10=1,if(GP10=1, -1, -2 ), if(GP10=1, 7, 0 ) ) ) -> 0 | GR10: 1 | GS10: =if(GO10=0,GQ10,GQ10*GR10) -> 0 | GT10: 1 | GU10: 1 | GV10: 1 | GW10: =if( GT10=1, if( GU10=1, if( GV10=1, 5, 3), if( GV10=1, 1, -3 ) ), if(GU10=1,if(GV10=1, -1, -2 ), if(GV10=1, 7, 0 ) ) ) -> 5 | GX10: 1 | GY10: =if(GU10=0,GW10,GW10*GX10) -> 5 | HC10: =if( GZ10=1, if( HA10=1, if( HB10=1, 5, 3), if( HB10=1, 1, -3 ) ), if(HA10=1,if(HB10=1, -1, -2 ), if(HB10=1, 7, 0 ) ) ) -> 0 | HD10: 1 | HE10: =if(HA10=0,HC10,HC10*HD10) -> 0 | HI10: =if( HF10=1, if( HG10=1, if( HH10=1, 5, 3), if( HH10=1, 1, -3 ) ), if(HG10=1,if(HH10=1, -1, -2 ), if(HH10=1, 7, 0 ) ) ) -> 0 | HJ10: 1 | HK10: =if(HG10=0,HI10,HI10*HJ10) -> 0 | HO10: =if( HL10=1, if( HM10=1, if( HN10=1, 5, 3), if( HN10=1, 1, -3 ) ), if(HM10=1,if(HN10=1, -1, -2 ), if(HN10=1, 7, 0 ) ) ) -> 0 | HP10: 1 | HQ10: =if(HM10=0,HO10,HO10*HP10) -> 0 | HU10: =if( HR10=1, if( HS10=1, if( HT10=1, 5, 3), if( HT10=1, 1, -3 ) ), if(HS10=1,if(HT10=1, -1, -2 ), if(HT10=1, 7, 0 ) ) ) -> 0 | HV10: 1 | HW10: =if(HS10=0,HU10,HU10*HV10) -> 0 | IA10: =if( HX10=1, if( HY10=1, if( HZ10=1, 5, 3), if( HZ10=1, 1, -3 ) ), if(HY10=1,if(HZ10=1, -1, -2 ), if(HZ10=1, 7, 0 ) ) ) -> 0 | IB10: 1 | IC10: =if(HY10=0,IA10,IA10*IB10) -> 0 | IG10: =if( ID10=1, if( IE10=1, if( IF10=1, 5, 3), if( IF10=1, 1, -3 ) ), if(IE10=1,if(IF10=1, -1, -2 ), if(IF10=1, 7, 0 ) ) ) -> 0 | IH10: 1 | II10: =if(IE10=0,IG10,IG10*IH10) -> 0 | IM10: =if( IJ10=1, if( IK10=1, if( IL10=1, 5, 3), if( IL10=1, 1, -3 ) ), if(IK10=1,if(IL10=1, -1, -2 ), if(IL10=1, 7, 0 ) ) ) -> 0 | IN10: 1 | IO10: =if(IK10=0,IM10,IM10*IN10) -> 0
A11: David | B11: Covid | C11: =countA($A$6:A11) -> 6 | D11: =VLOOKUP(A11,TDP!A:C,3,FALSE) -> 0.31 | E11: =(1+$D11)*sum($G11,$M11,$Q11,$U11,$AA11,$AG11,$AM11,$AS11,$AY11,$BE11,$BK11,$BQ11,$BW11,$CC11,$CI11,$CO11,$CU11,$DA11,$DG11,$DM11,$DS11,$DY11,$EE11,$EK11,$EQ11,$EW11,$FC11,$FI11,$FO11,$FU11,$GA11,$GG11,$GM11,$GS11,$GY11,$HE11,$HK11,$HQ11,$HW11,$IC11,$II11,$IO11) -> 153.27 | G11: =if(F11=1, 7, 0 ) -> 0 | H11: 1 | I11: 1 | J11: 1 | K11: =if( H11=1, if( I11=1, if( J11=1, 5, 3), if( J11=1, 1, -3 ) ), if(I11=1,if(J11=1, -1, -2 ), if(J11=1, 7, 0 ) ) ) -> 5 | L11: 1 | M11: =if(I11=0,K11,K11*L11) -> 5 | Q11: =if( N11=1, if( O11=1, if( P11=1, 5, 3), if( P11=1, 1, -3 ) ), if(O11=1,if(P11=1, -1, -2 ), if(P11=1, 7, 0 ) ) ) -> 0 | U11: =if( R11=1, if( S11=1, if( T11=1, 5, 3), if( T11=1, 1, -3 ) ), if(S11=1,if(T11=1, -1, -2 ), if(T11=1, 7, 0 ) ) ) -> 0 | Y11: =if( V11=1, if( W11=1, if( X11=1, 5, 3), if( X11=1, 1, -3 ) ), if(W11=1,if(X11=1, -1, -2 ), if(X11=1, 7, 0 ) ) ) -> 0 | AA11: =if(W11=0,Y11,Y11*Z11) -> 0 | AE11: =if( AB11=1, if( AC11=1, if( AD11=1, 5, 3), if( AD11=1, 1, -3 ) ), if(AC11=1,if(AD11=1, -1, -2 ), if(AD11=1, 7, 0 ) ) ) -> 0 | AG11: =if(AC11=0,AE11,AE11*AF11) -> 0 | AJ11: 1 | AK11: =if( AH11=1, if( AI11=1, if( AJ11=1, 5, 3), if( AJ11=1, 1, -3 ) ), if(AI11=1,if(AJ11=1, -1, -2 ), if(AJ11=1, 7, 0 ) ) ) -> 7 | AM11: =if(AI11=0,AK11,AK11*AL11) -> 7 | AP11: 1 | AQ11: =if( AN11=1, if( AO11=1, if( AP11=1, 5, 3), if( AP11=1, 1, -3 ) ), if(AO11=1,if(AP11=1, -1, -2 ), if(AP11=1, 7, 0 ) ) ) -> 7 | AS11: =if(AO11=0,AQ11,AQ11*AR11) -> 7 | AT11: 1 | AU11: 1 | AV11: 1 | AW11: =if( AT11=1, if( AU11=1, if( AV11=1, 5, 3), if( AV11=1, 1, -3 ) ), if(AU11=1,if(AV11=1, -1, -2 ), if(AV11=1, 7, 0 ) ) ) -> 5 | AX11: 1 | AY11: =if(AU11=0,AW11,AW11*AX11) -> 5 | AZ11: 1 | BA11: 1 | BB11: 1 | BC11: =if( AZ11=1, if( BA11=1, if( BB11=1, 5, 3), if( BB11=1, 1, -3 ) ), if(BA11=1,if(BB11=1, -1, -2 ), if(BB11=1, 7, 0 ) ) ) -> 5 | BD11: 1 | BE11: =if(BA11=0,BC11,BC11*BD11) -> 5 | BF11: 1 | BG11: 1 | BI11: =if( BF11=1, if( BG11=1, if( BH11=1, 5, 3), if( BH11=1, 1, -3 ) ), if(BG11=1,if(BH11=1, -1, -2 ), if(BH11=1, 7, 0 ) ) ) -> 3 | BJ11: 1 | BK11: =if(BG11=0,BI11,BI11*BJ11) -> 3 | BL11: 1 | BM11: 1 | BN11: 1 | BO11: =if( BL11=1, if( BM11=1, if( BN11=1, 5, 3), if( BN11=1, 1, -3 ) ), if(BM11=1,if(BN11=1, -1, -2 ), if(BN11=1, 7, 0 ) ) ) -> 5 | BP11: 1 | BQ11: =if(BM11=0,BO11,BO11*BP11) -> 5 | BT11: 1 | BU11: =if( BR11=1, if( BS11=1, if( BT11=1, 5, 3), if( BT11=1, 1, -3 ) ), if(BS11=1,if(BT11=1, -1, -2 ), if(BT11=1, 7, 0 ) ) ) -> 7 | BW11: =if(BS11=0,BU11,BU11*BV11) -> 7 | BX11: 1 | BY11: 1 | BZ11: 1 | CA11: =if( BX11=1, if( BY11=1, if( BZ11=1, 5, 3), if( BZ11=1, 1, -3 ) ), if(BY11=1,if(BZ11=1, -1, -2 ), if(BZ11=1, 7, 0 ) ) ) -> 5 | CB11: 1 | CC11: =if(BY11=0,CA11,CA11*CB11) -> 5 | CD11: 1 | CE11: 1 | CF11: 1 | CG11: =if( CD11=1, if( CE11=1, if( CF11=1, 5, 3), if( CF11=1, 1, -3 ) ), if(CE11=1,if(CF11=1, -1, -2 ), if(CF11=1, 7, 0 ) ) ) -> 5 | CH11: 1 | CI11: =if(CE11=0,CG11,CG11*CH11) -> 5 | CM11: =if( CJ11=1, if( CK11=1, if( CL11=1, 5, 3), if( CL11=1, 1, -3 ) ), if(CK11=1,if(CL11=1, -1, -2 ), if(CL11=1, 7, 0 ) ) ) -> 0 | CO11: =if(CK11=0,CM11,CM11*CN11) -> 0 | CP11: 1 | CQ11: 1 | CS11: =if( CP11=1, if( CQ11=1, if( CR11=1, 5, 3), if( CR11=1, 1, -3 ) ), if(CQ11=1,if(CR11=1, -1, -2 ), if(CR11=1, 7, 0 ) ) ) -> 3 | CT11: 1 | CU11: =if(CQ11=0,CS11,CS11*CT11) -> 3 | CV11: 1 | CW11: 1 | CY11: =if( CV11=1, if( CW11=1, if( CX11=1, 5, 3), if( CX11=1, 1, -3 ) ), if(CW11=1,if(CX11=1, -1, -2 ), if(CX11=1, 7, 0 ) ) ) -> 3 | CZ11: 1 | DA11: =if(CW11=0,CY11,CY11*CZ11) -> 3 | DB11: 1 | DC11: 1 | DE11: =if( DB11=1, if( DC11=1, if( DD11=1, 5, 3), if( DD11=1, 1, -3 ) ), if(DC11=1,if(DD11=1, -1, -2 ), if(DD11=1, 7, 0 ) ) ) -> 3 | DF11: 1 | DG11: =if(DC11=0,DE11,DE11*DF11) -> 3 | DH11: 1 | DI11: 1 | DK11: =if( DH11=1, if( DI11=1, if( DJ11=1, 5, 3), if( DJ11=1, 1, -3 ) ), if(DI11=1,if(DJ11=1, -1, -2 ), if(DJ11=1, 7, 0 ) ) ) -> 3 | DL11: 1 | DM11: =if(DI11=0,DK11,DK11*DL11) -> 3 | DN11: 1 | DO11: 1 | DP11: 1 | DQ11: =if( DN11=1, if( DO11=1, if( DP11=1, 5, 3), if( DP11=1, 1, -3 ) ), if(DO11=1,if(DP11=1, -1, -2 ), if(DP11=1, 7, 0 ) ) ) -> 5 | DR11: 1 | DS11: =if(DO11=0,DQ11,DQ11*DR11) -> 5 | DT11: 1 | DU11: 1 | DV11: 1 | DW11: =if( DT11=1, if( DU11=1, if( DV11=1, 5, 3), if( DV11=1, 1, -3 ) ), if(DU11=1,if(DV11=1, -1, -2 ), if(DV11=1, 7, 0 ) ) ) -> 5 | DX11: 1 | DY11: =if(DU11=0,DW11,DW11*DX11) -> 5 | DZ11: 1 | EA11: 1 | EC11: =if( DZ11=1, if( EA11=1, if( EB11=1, 5, 3), if( EB11=1, 1, -3 ) ), if(EA11=1,if(EB11=1, -1, -2 ), if(EB11=1, 7, 0 ) ) ) -> 3 | ED11: 1 | EE11: =if(EA11=0,EC11,EC11*ED11) -> 3 | EF11: 1 | EG11: 1 | EI11: =if( EF11=1, if( EG11=1, if( EH11=1, 5, 3), if( EH11=1, 1, -3 ) ), if(EG11=1,if(EH11=1, -1, -2 ), if(EH11=1, 7, 0 ) ) ) -> 3 | EJ11: 1 | EK11: =if(EG11=0,EI11,EI11*EJ11) -> 3 | EL11: 1 | EM11: 1 | EO11: =if( EL11=1, if( EM11=1, if( EN11=1, 5, 3), if( EN11=1, 1, -3 ) ), if(EM11=1,if(EN11=1, -1, -2 ), if(EN11=1, 7, 0 ) ) ) -> 3 | EP11: 1 | EQ11: =if(EM11=0,EO11,EO11*EP11) -> 3 | ER11: 1 | ES11: 1 | EU11: =if( ER11=1, if( ES11=1, if( ET11=1, 5, 3), if( ET11=1, 1, -3 ) ), if(ES11=1,if(ET11=1, -1, -2 ), if(ET11=1, 7, 0 ) ) ) -> 3 | EV11: 1 | EW11: =if(ES11=0,EU11,EU11*EV11) -> 3 | EX11: 1 | EY11: 1 | EZ11: 1 | FA11: =if( EX11=1, if( EY11=1, if( EZ11=1, 5, 3), if( EZ11=1, 1, -3 ) ), if(EY11=1,if(EZ11=1, -1, -2 ), if(EZ11=1, 7, 0 ) ) ) -> 5 | FB11: 1 | FC11: =if(EY11=0,FA11,FA11*FB11) -> 5 | FG11: =if( FD11=1, if( FE11=1, if( FF11=1, 5, 3), if( FF11=1, 1, -3 ) ), if(FE11=1,if(FF11=1, -1, -2 ), if(FF11=1, 7, 0 ) ) ) -> 0 | FH11: 1 | FI11: =if(FE11=0,FG11,FG11*FH11) -> 0 | FM11: =if( FJ11=1, if( FK11=1, if( FL11=1, 5, 3), if( FL11=1, 1, -3 ) ), if(FK11=1,if(FL11=1, -1, -2 ), if(FL11=1, 7, 0 ) ) ) -> 0 | FN11: 1 | FO11: =if(FK11=0,FM11,FM11*FN11) -> 0 | FP11: 1 | FQ11: 1 | FR11: 1 | FS11: =if( FP11=1, if( FQ11=1, if( FR11=1, 5, 3), if( FR11=1, 1, -3 ) ), if(FQ11=1,if(FR11=1, -1, -2 ), if(FR11=1, 7, 0 ) ) ) -> 5 | FT11: 1 | FU11: =if(FQ11=0,FS11,FS11*FT11) -> 5 | FV11: 1 | FW11: 1 | FY11: =if( FV11=1, if( FW11=1, if( FX11=1, 5, 3), if( FX11=1, 1, -3 ) ), if(FW11=1,if(FX11=1, -1, -2 ), if(FX11=1, 7, 0 ) ) ) -> 3 | FZ11: 1 | GA11: =if(FW11=0,FY11,FY11*FZ11) -> 3 | GB11: 1 | GC11: 1 | GE11: =if( GB11=1, if( GC11=1, if( GD11=1, 5, 3), if( GD11=1, 1, -3 ) ), if(GC11=1,if(GD11=1, -1, -2 ), if(GD11=1, 7, 0 ) ) ) -> 3 | GF11: 1 | GG11: =if(GC11=0,GE11,GE11*GF11) -> 3 | GK11: =if( GH11=1, if( GI11=1, if( GJ11=1, 5, 3), if( GJ11=1, 1, -3 ) ), if(GI11=1,if(GJ11=1, -1, -2 ), if(GJ11=1, 7, 0 ) ) ) -> 0 | GL11: 1 | GM11: =if(GI11=0,GK11,GK11*GL11) -> 0 | GQ11: =if( GN11=1, if( GO11=1, if( GP11=1, 5, 3), if( GP11=1, 1, -3 ) ), if(GO11=1,if(GP11=1, -1, -2 ), if(GP11=1, 7, 0 ) ) ) -> 0 | GR11: 1 | GS11: =if(GO11=0,GQ11,GQ11*GR11) -> 0 | GT11: 1 | GU11: 1 | GV11: 1 | GW11: =if( GT11=1, if( GU11=1, if( GV11=1, 5, 3), if( GV11=1, 1, -3 ) ), if(GU11=1,if(GV11=1, -1, -2 ), if(GV11=1, 7, 0 ) ) ) -> 5 | GX11: 1 | GY11: =if(GU11=0,GW11,GW11*GX11) -> 5 | GZ11: 1 | HA11: 1 | HC11: =if( GZ11=1, if( HA11=1, if( HB11=1, 5, 3), if( HB11=1, 1, -3 ) ), if(HA11=1,if(HB11=1, -1, -2 ), if(HB11=1, 7, 0 ) ) ) -> 3 | HD11: 1 | HE11: =if(HA11=0,HC11,HC11*HD11) -> 3 | HF11: 1 | HG11: 1 | HH11: 1 | HI11: =if( HF11=1, if( HG11=1, if( HH11=1, 5, 3), if( HH11=1, 1, -3 ) ), if(HG11=1,if(HH11=1, -1, -2 ), if(HH11=1, 7, 0 ) ) ) -> 5 | HJ11: 1 | HK11: =if(HG11=0,HI11,HI11*HJ11) -> 5 | HO11: =if( HL11=1, if( HM11=1, if( HN11=1, 5, 3), if( HN11=1, 1, -3 ) ), if(HM11=1,if(HN11=1, -1, -2 ), if(HN11=1, 7, 0 ) ) ) -> 0 | HP11: 1 | HQ11: =if(HM11=0,HO11,HO11*HP11) -> 0 | HU11: =if( HR11=1, if( HS11=1, if( HT11=1, 5, 3), if( HT11=1, 1, -3 ) ), if(HS11=1,if(HT11=1, -1, -2 ), if(HT11=1, 7, 0 ) ) ) -> 0 | HV11: 1 | HW11: =if(HS11=0,HU11,HU11*HV11) -> 0 | IA11: =if( HX11=1, if( HY11=1, if( HZ11=1, 5, 3), if( HZ11=1, 1, -3 ) ), if(HY11=1,if(HZ11=1, -1, -2 ), if(HZ11=1, 7, 0 ) ) ) -> 0 | IB11: 1 | IC11: =if(HY11=0,IA11,IA11*IB11) -> 0 | IG11: =if( ID11=1, if( IE11=1, if( IF11=1, 5, 3), if( IF11=1, 1, -3 ) ), if(IE11=1,if(IF11=1, -1, -2 ), if(IF11=1, 7, 0 ) ) ) -> 0 | IH11: 1 | II11: =if(IE11=0,IG11,IG11*IH11) -> 0 | IM11: =if( IJ11=1, if( IK11=1, if( IL11=1, 5, 3), if( IL11=1, 1, -3 ) ), if(IK11=1,if(IL11=1, -1, -2 ), if(IL11=1, 7, 0 ) ) ) -> 0 | IN11: 1 | IO11: =if(IK11=0,IM11,IM11*IN11) -> 0
